ERROR 2025-02-28 10:55:40,315 log Internal Server Error: /api/accounts/register/
Traceback (most recent call last):
  File "/Users/elgiz/flyexpert/backend/.venv/lib/python3.13/site-packages/django/core/handlers/exception.py", line 55, in inner
    response = get_response(request)
  File "/Users/elgiz/flyexpert/backend/.venv/lib/python3.13/site-packages/django/core/handlers/base.py", line 197, in _get_response
    response = wrapped_callback(request, *callback_args, **callback_kwargs)
  File "/Users/elgiz/flyexpert/backend/.venv/lib/python3.13/site-packages/django/views/decorators/csrf.py", line 65, in _view_wrapper
    return view_func(request, *args, **kwargs)
  File "/Users/elgiz/flyexpert/backend/.venv/lib/python3.13/site-packages/django/views/generic/base.py", line 104, in view
    return self.dispatch(request, *args, **kwargs)
           ~~~~~~~~~~~~~^^^^^^^^^^^^^^^^^^^^^^^^^^
  File "/Users/elgiz/flyexpert/backend/.venv/lib/python3.13/site-packages/rest_framework/views.py", line 509, in dispatch
    response = self.handle_exception(exc)
  File "/Users/elgiz/flyexpert/backend/.venv/lib/python3.13/site-packages/rest_framework/views.py", line 469, in handle_exception
    self.raise_uncaught_exception(exc)
    ~~~~~~~~~~~~~~~~~~~~~~~~~~~~~^^^^^
  File "/Users/elgiz/flyexpert/backend/.venv/lib/python3.13/site-packages/rest_framework/views.py", line 480, in raise_uncaught_exception
    raise exc
  File "/Users/elgiz/flyexpert/backend/.venv/lib/python3.13/site-packages/rest_framework/views.py", line 506, in dispatch
    response = handler(request, *args, **kwargs)
  File "/Users/elgiz/flyexpert/backend/backend/accounts/views.py", line 63, in post
    send_mail(
    ~~~~~~~~~^
        'Email Təsdiqləmə Kodu',
        ^^^^^^^^^^^^^^^^^^^^^^^^
    ...<3 lines>...
        fail_silently=False,
        ^^^^^^^^^^^^^^^^^^^^
    )
    ^
  File "/Users/elgiz/flyexpert/backend/.venv/lib/python3.13/site-packages/django/core/mail/__init__.py", line 88, in send_mail
    return mail.send()
           ~~~~~~~~~^^
  File "/Users/elgiz/flyexpert/backend/.venv/lib/python3.13/site-packages/django/core/mail/message.py", line 301, in send
    return self.get_connection(fail_silently).send_messages([self])
           ~~~~~~~~~~~~~~~~~~~~~~~~~~~~~~~~~~~~~~~~~~~~~~~~^^^^^^^^
  File "/Users/elgiz/flyexpert/backend/.venv/lib/python3.13/site-packages/django/core/mail/backends/smtp.py", line 128, in send_messages
    new_conn_created = self.open()
  File "/Users/elgiz/flyexpert/backend/.venv/lib/python3.13/site-packages/django/core/mail/backends/smtp.py", line 86, in open
    self.connection = self.connection_class(
                      ~~~~~~~~~~~~~~~~~~~~~^
        self.host, self.port, **connection_params
        ^^^^^^^^^^^^^^^^^^^^^^^^^^^^^^^^^^^^^^^^^
    )
    ^
  File "/Library/Frameworks/Python.framework/Versions/3.13/lib/python3.13/smtplib.py", line 255, in __init__
    (code, msg) = self.connect(host, port)
                  ~~~~~~~~~~~~^^^^^^^^^^^^
  File "/Library/Frameworks/Python.framework/Versions/3.13/lib/python3.13/smtplib.py", line 341, in connect
    self.sock = self._get_socket(host, port, self.timeout)
                ~~~~~~~~~~~~~~~~^^^^^^^^^^^^^^^^^^^^^^^^^^
  File "/Library/Frameworks/Python.framework/Versions/3.13/lib/python3.13/smtplib.py", line 312, in _get_socket
    return socket.create_connection((host, port), timeout,
           ~~~~~~~~~~~~~~~~~~~~~~~~^^^^^^^^^^^^^^^^^^^^^^^
                                    self.source_address)
                                    ^^^^^^^^^^^^^^^^^^^^
  File "/Library/Frameworks/Python.framework/Versions/3.13/lib/python3.13/socket.py", line 864, in create_connection
    raise exceptions[0]
  File "/Library/Frameworks/Python.framework/Versions/3.13/lib/python3.13/socket.py", line 849, in create_connection
    sock.connect(sa)
    ~~~~~~~~~~~~^^^^
ConnectionRefusedError: [Errno 61] Connection refused
ERROR 2025-02-28 10:55:40,319 basehttp "POST /api/accounts/register/ HTTP/1.1" 500 131809
ERROR 2025-02-28 10:55:56,860 log Internal Server Error: /api/accounts/register/
Traceback (most recent call last):
  File "/Users/elgiz/flyexpert/backend/.venv/lib/python3.13/site-packages/django/core/handlers/exception.py", line 55, in inner
    response = get_response(request)
  File "/Users/elgiz/flyexpert/backend/.venv/lib/python3.13/site-packages/django/core/handlers/base.py", line 197, in _get_response
    response = wrapped_callback(request, *callback_args, **callback_kwargs)
  File "/Users/elgiz/flyexpert/backend/.venv/lib/python3.13/site-packages/django/views/decorators/csrf.py", line 65, in _view_wrapper
    return view_func(request, *args, **kwargs)
  File "/Users/elgiz/flyexpert/backend/.venv/lib/python3.13/site-packages/django/views/generic/base.py", line 104, in view
    return self.dispatch(request, *args, **kwargs)
           ~~~~~~~~~~~~~^^^^^^^^^^^^^^^^^^^^^^^^^^
  File "/Users/elgiz/flyexpert/backend/.venv/lib/python3.13/site-packages/rest_framework/views.py", line 509, in dispatch
    response = self.handle_exception(exc)
  File "/Users/elgiz/flyexpert/backend/.venv/lib/python3.13/site-packages/rest_framework/views.py", line 469, in handle_exception
    self.raise_uncaught_exception(exc)
    ~~~~~~~~~~~~~~~~~~~~~~~~~~~~~^^^^^
  File "/Users/elgiz/flyexpert/backend/.venv/lib/python3.13/site-packages/rest_framework/views.py", line 480, in raise_uncaught_exception
    raise exc
  File "/Users/elgiz/flyexpert/backend/.venv/lib/python3.13/site-packages/rest_framework/views.py", line 506, in dispatch
    response = handler(request, *args, **kwargs)
  File "/Users/elgiz/flyexpert/backend/backend/accounts/views.py", line 63, in post
    send_mail(
    ~~~~~~~~~^
        'Email Təsdiqləmə Kodu',
        ^^^^^^^^^^^^^^^^^^^^^^^^
    ...<3 lines>...
        fail_silently=False,
        ^^^^^^^^^^^^^^^^^^^^
    )
    ^
  File "/Users/elgiz/flyexpert/backend/.venv/lib/python3.13/site-packages/django/core/mail/__init__.py", line 88, in send_mail
    return mail.send()
           ~~~~~~~~~^^
  File "/Users/elgiz/flyexpert/backend/.venv/lib/python3.13/site-packages/django/core/mail/message.py", line 301, in send
    return self.get_connection(fail_silently).send_messages([self])
           ~~~~~~~~~~~~~~~~~~~~~~~~~~~~~~~~~~~~~~~~~~~~~~~~^^^^^^^^
  File "/Users/elgiz/flyexpert/backend/.venv/lib/python3.13/site-packages/django/core/mail/backends/smtp.py", line 128, in send_messages
    new_conn_created = self.open()
  File "/Users/elgiz/flyexpert/backend/.venv/lib/python3.13/site-packages/django/core/mail/backends/smtp.py", line 86, in open
    self.connection = self.connection_class(
                      ~~~~~~~~~~~~~~~~~~~~~^
        self.host, self.port, **connection_params
        ^^^^^^^^^^^^^^^^^^^^^^^^^^^^^^^^^^^^^^^^^
    )
    ^
  File "/Library/Frameworks/Python.framework/Versions/3.13/lib/python3.13/smtplib.py", line 255, in __init__
    (code, msg) = self.connect(host, port)
                  ~~~~~~~~~~~~^^^^^^^^^^^^
  File "/Library/Frameworks/Python.framework/Versions/3.13/lib/python3.13/smtplib.py", line 341, in connect
    self.sock = self._get_socket(host, port, self.timeout)
                ~~~~~~~~~~~~~~~~^^^^^^^^^^^^^^^^^^^^^^^^^^
  File "/Library/Frameworks/Python.framework/Versions/3.13/lib/python3.13/smtplib.py", line 312, in _get_socket
    return socket.create_connection((host, port), timeout,
           ~~~~~~~~~~~~~~~~~~~~~~~~^^^^^^^^^^^^^^^^^^^^^^^
                                    self.source_address)
                                    ^^^^^^^^^^^^^^^^^^^^
  File "/Library/Frameworks/Python.framework/Versions/3.13/lib/python3.13/socket.py", line 864, in create_connection
    raise exceptions[0]
  File "/Library/Frameworks/Python.framework/Versions/3.13/lib/python3.13/socket.py", line 849, in create_connection
    sock.connect(sa)
    ~~~~~~~~~~~~^^^^
ConnectionRefusedError: [Errno 61] Connection refused
ERROR 2025-02-28 10:55:56,864 basehttp "POST /api/accounts/register/ HTTP/1.1" 500 131822
ERROR 2025-02-28 10:56:25,402 log Internal Server Error: /api/accounts/register/
Traceback (most recent call last):
  File "/Users/elgiz/flyexpert/backend/.venv/lib/python3.13/site-packages/django/core/handlers/exception.py", line 55, in inner
    response = get_response(request)
  File "/Users/elgiz/flyexpert/backend/.venv/lib/python3.13/site-packages/django/core/handlers/base.py", line 197, in _get_response
    response = wrapped_callback(request, *callback_args, **callback_kwargs)
  File "/Users/elgiz/flyexpert/backend/.venv/lib/python3.13/site-packages/django/views/decorators/csrf.py", line 65, in _view_wrapper
    return view_func(request, *args, **kwargs)
  File "/Users/elgiz/flyexpert/backend/.venv/lib/python3.13/site-packages/django/views/generic/base.py", line 104, in view
    return self.dispatch(request, *args, **kwargs)
           ~~~~~~~~~~~~~^^^^^^^^^^^^^^^^^^^^^^^^^^
  File "/Users/elgiz/flyexpert/backend/.venv/lib/python3.13/site-packages/rest_framework/views.py", line 509, in dispatch
    response = self.handle_exception(exc)
  File "/Users/elgiz/flyexpert/backend/.venv/lib/python3.13/site-packages/rest_framework/views.py", line 469, in handle_exception
    self.raise_uncaught_exception(exc)
    ~~~~~~~~~~~~~~~~~~~~~~~~~~~~~^^^^^
  File "/Users/elgiz/flyexpert/backend/.venv/lib/python3.13/site-packages/rest_framework/views.py", line 480, in raise_uncaught_exception
    raise exc
  File "/Users/elgiz/flyexpert/backend/.venv/lib/python3.13/site-packages/rest_framework/views.py", line 506, in dispatch
    response = handler(request, *args, **kwargs)
  File "/Users/elgiz/flyexpert/backend/backend/accounts/views.py", line 63, in post
    send_mail(
    ~~~~~~~~~^
        'Email Təsdiqləmə Kodu',
        ^^^^^^^^^^^^^^^^^^^^^^^^
    ...<3 lines>...
        fail_silently=False,
        ^^^^^^^^^^^^^^^^^^^^
    )
    ^
  File "/Users/elgiz/flyexpert/backend/.venv/lib/python3.13/site-packages/django/core/mail/__init__.py", line 88, in send_mail
    return mail.send()
           ~~~~~~~~~^^
  File "/Users/elgiz/flyexpert/backend/.venv/lib/python3.13/site-packages/django/core/mail/message.py", line 301, in send
    return self.get_connection(fail_silently).send_messages([self])
           ~~~~~~~~~~~~~~~~~~~~~~~~~~~~~~~~~~~~~~~~~~~~~~~~^^^^^^^^
  File "/Users/elgiz/flyexpert/backend/.venv/lib/python3.13/site-packages/django/core/mail/backends/smtp.py", line 128, in send_messages
    new_conn_created = self.open()
  File "/Users/elgiz/flyexpert/backend/.venv/lib/python3.13/site-packages/django/core/mail/backends/smtp.py", line 86, in open
    self.connection = self.connection_class(
                      ~~~~~~~~~~~~~~~~~~~~~^
        self.host, self.port, **connection_params
        ^^^^^^^^^^^^^^^^^^^^^^^^^^^^^^^^^^^^^^^^^
    )
    ^
  File "/Library/Frameworks/Python.framework/Versions/3.13/lib/python3.13/smtplib.py", line 255, in __init__
    (code, msg) = self.connect(host, port)
                  ~~~~~~~~~~~~^^^^^^^^^^^^
  File "/Library/Frameworks/Python.framework/Versions/3.13/lib/python3.13/smtplib.py", line 341, in connect
    self.sock = self._get_socket(host, port, self.timeout)
                ~~~~~~~~~~~~~~~~^^^^^^^^^^^^^^^^^^^^^^^^^^
  File "/Library/Frameworks/Python.framework/Versions/3.13/lib/python3.13/smtplib.py", line 312, in _get_socket
    return socket.create_connection((host, port), timeout,
           ~~~~~~~~~~~~~~~~~~~~~~~~^^^^^^^^^^^^^^^^^^^^^^^
                                    self.source_address)
                                    ^^^^^^^^^^^^^^^^^^^^
  File "/Library/Frameworks/Python.framework/Versions/3.13/lib/python3.13/socket.py", line 864, in create_connection
    raise exceptions[0]
  File "/Library/Frameworks/Python.framework/Versions/3.13/lib/python3.13/socket.py", line 849, in create_connection
    sock.connect(sa)
    ~~~~~~~~~~~~^^^^
ConnectionRefusedError: [Errno 61] Connection refused
ERROR 2025-02-28 10:56:25,417 basehttp "POST /api/accounts/register/ HTTP/1.1" 500 131815
ERROR 2025-03-01 19:58:10,257 log Internal Server Error: /az/admin/tours/booking/add/
Traceback (most recent call last):
  File "/Users/elgiz/flyexpert/backend/.venv/lib/python3.13/site-packages/django/db/backends/utils.py", line 105, in _execute
    return self.cursor.execute(sql, params)
           ~~~~~~~~~~~~~~~~~~~^^^^^^^^^^^^^
  File "/Users/elgiz/flyexpert/backend/.venv/lib/python3.13/site-packages/django/db/backends/sqlite3/base.py", line 354, in execute
    return super().execute(query, params)
           ~~~~~~~~~~~~~~~^^^^^^^^^^^^^^^
sqlite3.OperationalError: table tours_booking has no column named status

The above exception was the direct cause of the following exception:

Traceback (most recent call last):
  File "/Users/elgiz/flyexpert/backend/.venv/lib/python3.13/site-packages/django/core/handlers/exception.py", line 55, in inner
    response = get_response(request)
  File "/Users/elgiz/flyexpert/backend/.venv/lib/python3.13/site-packages/django/core/handlers/base.py", line 197, in _get_response
    response = wrapped_callback(request, *callback_args, **callback_kwargs)
  File "/Users/elgiz/flyexpert/backend/.venv/lib/python3.13/site-packages/django/contrib/admin/options.py", line 718, in wrapper
    return self.admin_site.admin_view(view)(*args, **kwargs)
           ~~~~~~~~~~~~~~~~~~~~~~~~~~~~~~~~^^^^^^^^^^^^^^^^^
  File "/Users/elgiz/flyexpert/backend/.venv/lib/python3.13/site-packages/django/utils/decorators.py", line 188, in _view_wrapper
    result = _process_exception(request, e)
  File "/Users/elgiz/flyexpert/backend/.venv/lib/python3.13/site-packages/django/utils/decorators.py", line 186, in _view_wrapper
    response = view_func(request, *args, **kwargs)
  File "/Users/elgiz/flyexpert/backend/.venv/lib/python3.13/site-packages/django/views/decorators/cache.py", line 80, in _view_wrapper
    response = view_func(request, *args, **kwargs)
  File "/Users/elgiz/flyexpert/backend/.venv/lib/python3.13/site-packages/django/contrib/admin/sites.py", line 241, in inner
    return view(request, *args, **kwargs)
  File "/Users/elgiz/flyexpert/backend/.venv/lib/python3.13/site-packages/django/contrib/admin/options.py", line 1961, in add_view
    return self.changeform_view(request, None, form_url, extra_context)
           ~~~~~~~~~~~~~~~~~~~~^^^^^^^^^^^^^^^^^^^^^^^^^^^^^^^^^^^^^^^^
  File "/Users/elgiz/flyexpert/backend/.venv/lib/python3.13/site-packages/django/utils/decorators.py", line 48, in _wrapper
    return bound_method(*args, **kwargs)
  File "/Users/elgiz/flyexpert/backend/.venv/lib/python3.13/site-packages/django/utils/decorators.py", line 188, in _view_wrapper
    result = _process_exception(request, e)
  File "/Users/elgiz/flyexpert/backend/.venv/lib/python3.13/site-packages/django/utils/decorators.py", line 186, in _view_wrapper
    response = view_func(request, *args, **kwargs)
  File "/Users/elgiz/flyexpert/backend/.venv/lib/python3.13/site-packages/django/contrib/admin/options.py", line 1820, in changeform_view
    return self._changeform_view(request, object_id, form_url, extra_context)
           ~~~~~~~~~~~~~~~~~~~~~^^^^^^^^^^^^^^^^^^^^^^^^^^^^^^^^^^^^^^^^^^^^^
  File "/Users/elgiz/flyexpert/backend/.venv/lib/python3.13/site-packages/django/contrib/admin/options.py", line 1871, in _changeform_view
    self.save_model(request, new_object, form, not add)
    ~~~~~~~~~~~~~~~^^^^^^^^^^^^^^^^^^^^^^^^^^^^^^^^^^^^
  File "/Users/elgiz/flyexpert/backend/.venv/lib/python3.13/site-packages/django/contrib/admin/options.py", line 1294, in save_model
    obj.save()
    ~~~~~~~~^^
  File "/Users/elgiz/flyexpert/backend/tours/models.py", line 67, in save
    super().save(*args, **kwargs)
    ~~~~~~~~~~~~^^^^^^^^^^^^^^^^^
  File "/Users/elgiz/flyexpert/backend/.venv/lib/python3.13/site-packages/django/db/models/base.py", line 892, in save
    self.save_base(
    ~~~~~~~~~~~~~~^
        using=using,
        ^^^^^^^^^^^^
    ...<2 lines>...
        update_fields=update_fields,
        ^^^^^^^^^^^^^^^^^^^^^^^^^^^^
    )
    ^
  File "/Users/elgiz/flyexpert/backend/.venv/lib/python3.13/site-packages/django/db/models/base.py", line 998, in save_base
    updated = self._save_table(
        raw,
    ...<4 lines>...
        update_fields,
    )
  File "/Users/elgiz/flyexpert/backend/.venv/lib/python3.13/site-packages/django/db/models/base.py", line 1161, in _save_table
    results = self._do_insert(
        cls._base_manager, using, fields, returning_fields, raw
    )
  File "/Users/elgiz/flyexpert/backend/.venv/lib/python3.13/site-packages/django/db/models/base.py", line 1202, in _do_insert
    return manager._insert(
           ~~~~~~~~~~~~~~~^
        [self],
        ^^^^^^^
    ...<3 lines>...
        raw=raw,
        ^^^^^^^^
    )
    ^
  File "/Users/elgiz/flyexpert/backend/.venv/lib/python3.13/site-packages/django/db/models/manager.py", line 87, in manager_method
    return getattr(self.get_queryset(), name)(*args, **kwargs)
           ~~~~~~~~~~~~~~~~~~~~~~~~~~~~~~~~~~^^^^^^^^^^^^^^^^^
  File "/Users/elgiz/flyexpert/backend/.venv/lib/python3.13/site-packages/django/db/models/query.py", line 1847, in _insert
    return query.get_compiler(using=using).execute_sql(returning_fields)
           ~~~~~~~~~~~~~~~~~~~~~~~~~~~~~~~~~~~~~~~~~~~^^^^^^^^^^^^^^^^^^
  File "/Users/elgiz/flyexpert/backend/.venv/lib/python3.13/site-packages/django/db/models/sql/compiler.py", line 1836, in execute_sql
    cursor.execute(sql, params)
    ~~~~~~~~~~~~~~^^^^^^^^^^^^^
  File "/Users/elgiz/flyexpert/backend/.venv/lib/python3.13/site-packages/django/db/backends/utils.py", line 122, in execute
    return super().execute(sql, params)
           ~~~~~~~~~~~~~~~^^^^^^^^^^^^^
  File "/Users/elgiz/flyexpert/backend/.venv/lib/python3.13/site-packages/django/db/backends/utils.py", line 79, in execute
    return self._execute_with_wrappers(
           ~~~~~~~~~~~~~~~~~~~~~~~~~~~^
        sql, params, many=False, executor=self._execute
        ^^^^^^^^^^^^^^^^^^^^^^^^^^^^^^^^^^^^^^^^^^^^^^^
    )
    ^
  File "/Users/elgiz/flyexpert/backend/.venv/lib/python3.13/site-packages/django/db/backends/utils.py", line 92, in _execute_with_wrappers
    return executor(sql, params, many, context)
  File "/Users/elgiz/flyexpert/backend/.venv/lib/python3.13/site-packages/django/db/backends/utils.py", line 100, in _execute
    with self.db.wrap_database_errors:
         ^^^^^^^^^^^^^^^^^^^^^^^^^^^^
  File "/Users/elgiz/flyexpert/backend/.venv/lib/python3.13/site-packages/django/db/utils.py", line 91, in __exit__
    raise dj_exc_value.with_traceback(traceback) from exc_value
  File "/Users/elgiz/flyexpert/backend/.venv/lib/python3.13/site-packages/django/db/backends/utils.py", line 105, in _execute
    return self.cursor.execute(sql, params)
           ~~~~~~~~~~~~~~~~~~~^^^^^^^^^^^^^
  File "/Users/elgiz/flyexpert/backend/.venv/lib/python3.13/site-packages/django/db/backends/sqlite3/base.py", line 354, in execute
    return super().execute(query, params)
           ~~~~~~~~~~~~~~~^^^^^^^^^^^^^^^
django.db.utils.OperationalError: table tours_booking has no column named status
ERROR 2025-03-01 19:58:10,292 basehttp "POST /az/admin/tours/booking/add/ HTTP/1.1" 500 203431
ERROR 2025-03-01 19:58:40,343 log Internal Server Error: /tr/admin/tours/booking/add/
Traceback (most recent call last):
  File "/Users/elgiz/flyexpert/backend/.venv/lib/python3.13/site-packages/django/core/handlers/exception.py", line 55, in inner
    response = get_response(request)
  File "/Users/elgiz/flyexpert/backend/.venv/lib/python3.13/site-packages/django/core/handlers/base.py", line 197, in _get_response
    response = wrapped_callback(request, *callback_args, **callback_kwargs)
  File "/Users/elgiz/flyexpert/backend/.venv/lib/python3.13/site-packages/django/contrib/admin/options.py", line 718, in wrapper
    return self.admin_site.admin_view(view)(*args, **kwargs)
           ~~~~~~~~~~~~~~~~~~~~~~~~~~~~~~~~^^^^^^^^^^^^^^^^^
  File "/Users/elgiz/flyexpert/backend/.venv/lib/python3.13/site-packages/django/utils/decorators.py", line 188, in _view_wrapper
    result = _process_exception(request, e)
  File "/Users/elgiz/flyexpert/backend/.venv/lib/python3.13/site-packages/django/utils/decorators.py", line 186, in _view_wrapper
    response = view_func(request, *args, **kwargs)
  File "/Users/elgiz/flyexpert/backend/.venv/lib/python3.13/site-packages/django/views/decorators/cache.py", line 80, in _view_wrapper
    response = view_func(request, *args, **kwargs)
  File "/Users/elgiz/flyexpert/backend/.venv/lib/python3.13/site-packages/django/contrib/admin/sites.py", line 241, in inner
    return view(request, *args, **kwargs)
  File "/Users/elgiz/flyexpert/backend/.venv/lib/python3.13/site-packages/django/contrib/admin/options.py", line 1961, in add_view
    return self.changeform_view(request, None, form_url, extra_context)
           ~~~~~~~~~~~~~~~~~~~~^^^^^^^^^^^^^^^^^^^^^^^^^^^^^^^^^^^^^^^^
  File "/Users/elgiz/flyexpert/backend/.venv/lib/python3.13/site-packages/django/utils/decorators.py", line 48, in _wrapper
    return bound_method(*args, **kwargs)
  File "/Users/elgiz/flyexpert/backend/.venv/lib/python3.13/site-packages/django/utils/decorators.py", line 188, in _view_wrapper
    result = _process_exception(request, e)
  File "/Users/elgiz/flyexpert/backend/.venv/lib/python3.13/site-packages/django/utils/decorators.py", line 186, in _view_wrapper
    response = view_func(request, *args, **kwargs)
  File "/Users/elgiz/flyexpert/backend/.venv/lib/python3.13/site-packages/django/contrib/admin/options.py", line 1820, in changeform_view
    return self._changeform_view(request, object_id, form_url, extra_context)
           ~~~~~~~~~~~~~~~~~~~~~^^^^^^^^^^^^^^^^^^^^^^^^^^^^^^^^^^^^^^^^^^^^^
  File "/Users/elgiz/flyexpert/backend/.venv/lib/python3.13/site-packages/django/contrib/admin/options.py", line 1871, in _changeform_view
    self.save_model(request, new_object, form, not add)
    ~~~~~~~~~~~~~~~^^^^^^^^^^^^^^^^^^^^^^^^^^^^^^^^^^^^
  File "/Users/elgiz/flyexpert/backend/.venv/lib/python3.13/site-packages/django/contrib/admin/options.py", line 1294, in save_model
    obj.save()
    ~~~~~~~~^^
  File "/Users/elgiz/flyexpert/backend/tours/models.py", line 63, in save
    raise ValidationError("Bu tur üçün kifayət qədər yer yoxdur!")
django.core.exceptions.ValidationError: ['Bu tur üçün kifayət qədər yer yoxdur!']
ERROR 2025-03-01 19:58:40,360 basehttp "POST /tr/admin/tours/booking/add/ HTTP/1.1" 500 121855
ERROR 2025-03-01 19:59:09,997 log Internal Server Error: /az/admin/tours/booking/
Traceback (most recent call last):
  File "/Users/elgiz/flyexpert/backend/.venv/lib/python3.13/site-packages/django/db/backends/utils.py", line 105, in _execute
    return self.cursor.execute(sql, params)
           ~~~~~~~~~~~~~~~~~~~^^^^^^^^^^^^^
  File "/Users/elgiz/flyexpert/backend/.venv/lib/python3.13/site-packages/django/db/backends/sqlite3/base.py", line 354, in execute
    return super().execute(query, params)
           ~~~~~~~~~~~~~~~^^^^^^^^^^^^^^^
sqlite3.OperationalError: no such column: tours_booking.status

The above exception was the direct cause of the following exception:

Traceback (most recent call last):
  File "/Users/elgiz/flyexpert/backend/.venv/lib/python3.13/site-packages/django/core/handlers/exception.py", line 55, in inner
    response = get_response(request)
  File "/Users/elgiz/flyexpert/backend/.venv/lib/python3.13/site-packages/django/core/handlers/base.py", line 197, in _get_response
    response = wrapped_callback(request, *callback_args, **callback_kwargs)
  File "/Users/elgiz/flyexpert/backend/.venv/lib/python3.13/site-packages/django/contrib/admin/options.py", line 718, in wrapper
    return self.admin_site.admin_view(view)(*args, **kwargs)
           ~~~~~~~~~~~~~~~~~~~~~~~~~~~~~~~~^^^^^^^^^^^^^^^^^
  File "/Users/elgiz/flyexpert/backend/.venv/lib/python3.13/site-packages/django/utils/decorators.py", line 188, in _view_wrapper
    result = _process_exception(request, e)
  File "/Users/elgiz/flyexpert/backend/.venv/lib/python3.13/site-packages/django/utils/decorators.py", line 186, in _view_wrapper
    response = view_func(request, *args, **kwargs)
  File "/Users/elgiz/flyexpert/backend/.venv/lib/python3.13/site-packages/django/views/decorators/cache.py", line 80, in _view_wrapper
    response = view_func(request, *args, **kwargs)
  File "/Users/elgiz/flyexpert/backend/.venv/lib/python3.13/site-packages/django/contrib/admin/sites.py", line 241, in inner
    return view(request, *args, **kwargs)
  File "/Users/elgiz/flyexpert/backend/.venv/lib/python3.13/site-packages/django/utils/decorators.py", line 48, in _wrapper
    return bound_method(*args, **kwargs)
  File "/Users/elgiz/flyexpert/backend/.venv/lib/python3.13/site-packages/django/utils/decorators.py", line 188, in _view_wrapper
    result = _process_exception(request, e)
  File "/Users/elgiz/flyexpert/backend/.venv/lib/python3.13/site-packages/django/utils/decorators.py", line 186, in _view_wrapper
    response = view_func(request, *args, **kwargs)
  File "/Users/elgiz/flyexpert/backend/.venv/lib/python3.13/site-packages/django/contrib/admin/options.py", line 2121, in changelist_view
    media = self.media + formset.media
                         ^^^^^^^^^^^^^
  File "/Users/elgiz/flyexpert/backend/.venv/lib/python3.13/site-packages/django/forms/formsets.py", line 521, in media
    if self.forms:
       ^^^^^^^^^^
  File "/Users/elgiz/flyexpert/backend/.venv/lib/python3.13/site-packages/django/utils/functional.py", line 47, in __get__
    res = instance.__dict__[self.name] = self.func(instance)
                                         ~~~~~~~~~^^^^^^^^^^
  File "/Users/elgiz/flyexpert/backend/.venv/lib/python3.13/site-packages/django/forms/formsets.py", line 207, in forms
    for i in range(self.total_form_count())
                   ~~~~~~~~~~~~~~~~~~~~~^^
  File "/Users/elgiz/flyexpert/backend/.venv/lib/python3.13/site-packages/django/forms/formsets.py", line 182, in total_form_count
    initial_forms = self.initial_form_count()
  File "/Users/elgiz/flyexpert/backend/.venv/lib/python3.13/site-packages/django/forms/models.py", line 697, in initial_form_count
    return len(self.get_queryset())
  File "/Users/elgiz/flyexpert/backend/.venv/lib/python3.13/site-packages/django/db/models/query.py", line 382, in __len__
    self._fetch_all()
    ~~~~~~~~~~~~~~~^^
  File "/Users/elgiz/flyexpert/backend/.venv/lib/python3.13/site-packages/django/db/models/query.py", line 1928, in _fetch_all
    self._result_cache = list(self._iterable_class(self))
                         ~~~~^^^^^^^^^^^^^^^^^^^^^^^^^^^^
  File "/Users/elgiz/flyexpert/backend/.venv/lib/python3.13/site-packages/django/db/models/query.py", line 91, in __iter__
    results = compiler.execute_sql(
        chunked_fetch=self.chunked_fetch, chunk_size=self.chunk_size
    )
  File "/Users/elgiz/flyexpert/backend/.venv/lib/python3.13/site-packages/django/db/models/sql/compiler.py", line 1574, in execute_sql
    cursor.execute(sql, params)
    ~~~~~~~~~~~~~~^^^^^^^^^^^^^
  File "/Users/elgiz/flyexpert/backend/.venv/lib/python3.13/site-packages/django/db/backends/utils.py", line 122, in execute
    return super().execute(sql, params)
           ~~~~~~~~~~~~~~~^^^^^^^^^^^^^
  File "/Users/elgiz/flyexpert/backend/.venv/lib/python3.13/site-packages/django/db/backends/utils.py", line 79, in execute
    return self._execute_with_wrappers(
           ~~~~~~~~~~~~~~~~~~~~~~~~~~~^
        sql, params, many=False, executor=self._execute
        ^^^^^^^^^^^^^^^^^^^^^^^^^^^^^^^^^^^^^^^^^^^^^^^
    )
    ^
  File "/Users/elgiz/flyexpert/backend/.venv/lib/python3.13/site-packages/django/db/backends/utils.py", line 92, in _execute_with_wrappers
    return executor(sql, params, many, context)
  File "/Users/elgiz/flyexpert/backend/.venv/lib/python3.13/site-packages/django/db/backends/utils.py", line 100, in _execute
    with self.db.wrap_database_errors:
         ^^^^^^^^^^^^^^^^^^^^^^^^^^^^
  File "/Users/elgiz/flyexpert/backend/.venv/lib/python3.13/site-packages/django/db/utils.py", line 91, in __exit__
    raise dj_exc_value.with_traceback(traceback) from exc_value
  File "/Users/elgiz/flyexpert/backend/.venv/lib/python3.13/site-packages/django/db/backends/utils.py", line 105, in _execute
    return self.cursor.execute(sql, params)
           ~~~~~~~~~~~~~~~~~~~^^^^^^^^^^^^^
  File "/Users/elgiz/flyexpert/backend/.venv/lib/python3.13/site-packages/django/db/backends/sqlite3/base.py", line 354, in execute
    return super().execute(query, params)
           ~~~~~~~~~~~~~~~^^^^^^^^^^^^^^^
django.db.utils.OperationalError: no such column: tours_booking.status
ERROR 2025-03-01 19:59:10,020 basehttp "GET /az/admin/tours/booking/ HTTP/1.1" 500 197223
ERROR 2025-03-01 21:30:17,412 log Internal Server Error: /admin/tours/booking/
Traceback (most recent call last):
  File "/Users/elgiz/flyexpert/backend/.venv/lib/python3.13/site-packages/django/db/backends/utils.py", line 105, in _execute
    return self.cursor.execute(sql, params)
           ~~~~~~~~~~~~~~~~~~~^^^^^^^^^^^^^
  File "/Users/elgiz/flyexpert/backend/.venv/lib/python3.13/site-packages/django/db/backends/sqlite3/base.py", line 354, in execute
    return super().execute(query, params)
           ~~~~~~~~~~~~~~~^^^^^^^^^^^^^^^
sqlite3.OperationalError: no such column: tours_booking.status

The above exception was the direct cause of the following exception:

Traceback (most recent call last):
  File "/Users/elgiz/flyexpert/backend/.venv/lib/python3.13/site-packages/django/core/handlers/exception.py", line 55, in inner
    response = get_response(request)
  File "/Users/elgiz/flyexpert/backend/.venv/lib/python3.13/site-packages/django/core/handlers/base.py", line 197, in _get_response
    response = wrapped_callback(request, *callback_args, **callback_kwargs)
  File "/Users/elgiz/flyexpert/backend/.venv/lib/python3.13/site-packages/django/contrib/admin/options.py", line 718, in wrapper
    return self.admin_site.admin_view(view)(*args, **kwargs)
           ~~~~~~~~~~~~~~~~~~~~~~~~~~~~~~~~^^^^^^^^^^^^^^^^^
  File "/Users/elgiz/flyexpert/backend/.venv/lib/python3.13/site-packages/django/utils/decorators.py", line 188, in _view_wrapper
    result = _process_exception(request, e)
  File "/Users/elgiz/flyexpert/backend/.venv/lib/python3.13/site-packages/django/utils/decorators.py", line 186, in _view_wrapper
    response = view_func(request, *args, **kwargs)
  File "/Users/elgiz/flyexpert/backend/.venv/lib/python3.13/site-packages/django/views/decorators/cache.py", line 80, in _view_wrapper
    response = view_func(request, *args, **kwargs)
  File "/Users/elgiz/flyexpert/backend/.venv/lib/python3.13/site-packages/django/contrib/admin/sites.py", line 241, in inner
    return view(request, *args, **kwargs)
  File "/Users/elgiz/flyexpert/backend/.venv/lib/python3.13/site-packages/django/utils/decorators.py", line 48, in _wrapper
    return bound_method(*args, **kwargs)
  File "/Users/elgiz/flyexpert/backend/.venv/lib/python3.13/site-packages/django/utils/decorators.py", line 188, in _view_wrapper
    result = _process_exception(request, e)
  File "/Users/elgiz/flyexpert/backend/.venv/lib/python3.13/site-packages/django/utils/decorators.py", line 186, in _view_wrapper
    response = view_func(request, *args, **kwargs)
  File "/Users/elgiz/flyexpert/backend/.venv/lib/python3.13/site-packages/django/contrib/admin/options.py", line 2121, in changelist_view
    media = self.media + formset.media
                         ^^^^^^^^^^^^^
  File "/Users/elgiz/flyexpert/backend/.venv/lib/python3.13/site-packages/django/forms/formsets.py", line 521, in media
    if self.forms:
       ^^^^^^^^^^
  File "/Users/elgiz/flyexpert/backend/.venv/lib/python3.13/site-packages/django/utils/functional.py", line 47, in __get__
    res = instance.__dict__[self.name] = self.func(instance)
                                         ~~~~~~~~~^^^^^^^^^^
  File "/Users/elgiz/flyexpert/backend/.venv/lib/python3.13/site-packages/django/forms/formsets.py", line 207, in forms
    for i in range(self.total_form_count())
                   ~~~~~~~~~~~~~~~~~~~~~^^
  File "/Users/elgiz/flyexpert/backend/.venv/lib/python3.13/site-packages/django/forms/formsets.py", line 182, in total_form_count
    initial_forms = self.initial_form_count()
  File "/Users/elgiz/flyexpert/backend/.venv/lib/python3.13/site-packages/django/forms/models.py", line 697, in initial_form_count
    return len(self.get_queryset())
  File "/Users/elgiz/flyexpert/backend/.venv/lib/python3.13/site-packages/django/db/models/query.py", line 382, in __len__
    self._fetch_all()
    ~~~~~~~~~~~~~~~^^
  File "/Users/elgiz/flyexpert/backend/.venv/lib/python3.13/site-packages/django/db/models/query.py", line 1928, in _fetch_all
    self._result_cache = list(self._iterable_class(self))
                         ~~~~^^^^^^^^^^^^^^^^^^^^^^^^^^^^
  File "/Users/elgiz/flyexpert/backend/.venv/lib/python3.13/site-packages/django/db/models/query.py", line 91, in __iter__
    results = compiler.execute_sql(
        chunked_fetch=self.chunked_fetch, chunk_size=self.chunk_size
    )
  File "/Users/elgiz/flyexpert/backend/.venv/lib/python3.13/site-packages/django/db/models/sql/compiler.py", line 1574, in execute_sql
    cursor.execute(sql, params)
    ~~~~~~~~~~~~~~^^^^^^^^^^^^^
  File "/Users/elgiz/flyexpert/backend/.venv/lib/python3.13/site-packages/django/db/backends/utils.py", line 122, in execute
    return super().execute(sql, params)
           ~~~~~~~~~~~~~~~^^^^^^^^^^^^^
  File "/Users/elgiz/flyexpert/backend/.venv/lib/python3.13/site-packages/django/db/backends/utils.py", line 79, in execute
    return self._execute_with_wrappers(
           ~~~~~~~~~~~~~~~~~~~~~~~~~~~^
        sql, params, many=False, executor=self._execute
        ^^^^^^^^^^^^^^^^^^^^^^^^^^^^^^^^^^^^^^^^^^^^^^^
    )
    ^
  File "/Users/elgiz/flyexpert/backend/.venv/lib/python3.13/site-packages/django/db/backends/utils.py", line 92, in _execute_with_wrappers
    return executor(sql, params, many, context)
  File "/Users/elgiz/flyexpert/backend/.venv/lib/python3.13/site-packages/django/db/backends/utils.py", line 100, in _execute
    with self.db.wrap_database_errors:
         ^^^^^^^^^^^^^^^^^^^^^^^^^^^^
  File "/Users/elgiz/flyexpert/backend/.venv/lib/python3.13/site-packages/django/db/utils.py", line 91, in __exit__
    raise dj_exc_value.with_traceback(traceback) from exc_value
  File "/Users/elgiz/flyexpert/backend/.venv/lib/python3.13/site-packages/django/db/backends/utils.py", line 105, in _execute
    return self.cursor.execute(sql, params)
           ~~~~~~~~~~~~~~~~~~~^^^^^^^^^^^^^
  File "/Users/elgiz/flyexpert/backend/.venv/lib/python3.13/site-packages/django/db/backends/sqlite3/base.py", line 354, in execute
    return super().execute(query, params)
           ~~~~~~~~~~~~~~~^^^^^^^^^^^^^^^
django.db.utils.OperationalError: no such column: tours_booking.status
ERROR 2025-03-01 21:30:17,419 basehttp "GET /admin/tours/booking/ HTTP/1.1" 500 197313
ERROR 2025-03-01 15:56:11,886 log Internal Server Error: /admin/accounts/userprofile/
Traceback (most recent call last):
  File "/Users/elgiz/flyexpert/backend/.venv/lib/python3.13/site-packages/django/db/backends/utils.py", line 105, in _execute
    return self.cursor.execute(sql, params)
           ~~~~~~~~~~~~~~~~~~~^^^^^^^^^^^^^
  File "/Users/elgiz/flyexpert/backend/.venv/lib/python3.13/site-packages/django/db/backends/sqlite3/base.py", line 354, in execute
    return super().execute(query, params)
           ~~~~~~~~~~~~~~~^^^^^^^^^^^^^^^
sqlite3.OperationalError: no such table: accounts_userprofile

The above exception was the direct cause of the following exception:

Traceback (most recent call last):
  File "/Users/elgiz/flyexpert/backend/.venv/lib/python3.13/site-packages/django/core/handlers/exception.py", line 55, in inner
    response = get_response(request)
  File "/Users/elgiz/flyexpert/backend/.venv/lib/python3.13/site-packages/django/core/handlers/base.py", line 197, in _get_response
    response = wrapped_callback(request, *callback_args, **callback_kwargs)
  File "/Users/elgiz/flyexpert/backend/.venv/lib/python3.13/site-packages/django/contrib/admin/options.py", line 718, in wrapper
    return self.admin_site.admin_view(view)(*args, **kwargs)
           ~~~~~~~~~~~~~~~~~~~~~~~~~~~~~~~~^^^^^^^^^^^^^^^^^
  File "/Users/elgiz/flyexpert/backend/.venv/lib/python3.13/site-packages/django/utils/decorators.py", line 188, in _view_wrapper
    result = _process_exception(request, e)
  File "/Users/elgiz/flyexpert/backend/.venv/lib/python3.13/site-packages/django/utils/decorators.py", line 186, in _view_wrapper
    response = view_func(request, *args, **kwargs)
  File "/Users/elgiz/flyexpert/backend/.venv/lib/python3.13/site-packages/django/views/decorators/cache.py", line 80, in _view_wrapper
    response = view_func(request, *args, **kwargs)
  File "/Users/elgiz/flyexpert/backend/.venv/lib/python3.13/site-packages/django/contrib/admin/sites.py", line 241, in inner
    return view(request, *args, **kwargs)
  File "/Users/elgiz/flyexpert/backend/.venv/lib/python3.13/site-packages/django/utils/decorators.py", line 48, in _wrapper
    return bound_method(*args, **kwargs)
  File "/Users/elgiz/flyexpert/backend/.venv/lib/python3.13/site-packages/django/utils/decorators.py", line 188, in _view_wrapper
    result = _process_exception(request, e)
  File "/Users/elgiz/flyexpert/backend/.venv/lib/python3.13/site-packages/django/utils/decorators.py", line 186, in _view_wrapper
    response = view_func(request, *args, **kwargs)
  File "/Users/elgiz/flyexpert/backend/.venv/lib/python3.13/site-packages/django/contrib/admin/options.py", line 2001, in changelist_view
    cl = self.get_changelist_instance(request)
  File "/Users/elgiz/flyexpert/backend/.venv/lib/python3.13/site-packages/django/contrib/admin/options.py", line 866, in get_changelist_instance
    return ChangeList(
        request,
    ...<12 lines>...
        self.search_help_text,
    )
  File "/Users/elgiz/flyexpert/backend/.venv/lib/python3.13/site-packages/django/contrib/admin/views/main.py", line 146, in __init__
    self.get_results(request)
    ~~~~~~~~~~~~~~~~^^^^^^^^^
  File "/Users/elgiz/flyexpert/backend/.venv/lib/python3.13/site-packages/django/contrib/admin/views/main.py", line 313, in get_results
    result_count = paginator.count
                   ^^^^^^^^^^^^^^^
  File "/Users/elgiz/flyexpert/backend/.venv/lib/python3.13/site-packages/django/utils/functional.py", line 47, in __get__
    res = instance.__dict__[self.name] = self.func(instance)
                                         ~~~~~~~~~^^^^^^^^^^
  File "/Users/elgiz/flyexpert/backend/.venv/lib/python3.13/site-packages/django/core/paginator.py", line 110, in count
    return c()
  File "/Users/elgiz/flyexpert/backend/.venv/lib/python3.13/site-packages/django/db/models/query.py", line 620, in count
    return self.query.get_count(using=self.db)
           ~~~~~~~~~~~~~~~~~~~~^^^^^^^^^^^^^^^
  File "/Users/elgiz/flyexpert/backend/.venv/lib/python3.13/site-packages/django/db/models/sql/query.py", line 630, in get_count
    return obj.get_aggregation(using, {"__count": Count("*")})["__count"]
           ~~~~~~~~~~~~~~~~~~~^^^^^^^^^^^^^^^^^^^^^^^^^^^^^^^^
  File "/Users/elgiz/flyexpert/backend/.venv/lib/python3.13/site-packages/django/db/models/sql/query.py", line 616, in get_aggregation
    result = compiler.execute_sql(SINGLE)
  File "/Users/elgiz/flyexpert/backend/.venv/lib/python3.13/site-packages/django/db/models/sql/compiler.py", line 1574, in execute_sql
    cursor.execute(sql, params)
    ~~~~~~~~~~~~~~^^^^^^^^^^^^^
  File "/Users/elgiz/flyexpert/backend/.venv/lib/python3.13/site-packages/django/db/backends/utils.py", line 122, in execute
    return super().execute(sql, params)
           ~~~~~~~~~~~~~~~^^^^^^^^^^^^^
  File "/Users/elgiz/flyexpert/backend/.venv/lib/python3.13/site-packages/django/db/backends/utils.py", line 79, in execute
    return self._execute_with_wrappers(
           ~~~~~~~~~~~~~~~~~~~~~~~~~~~^
        sql, params, many=False, executor=self._execute
        ^^^^^^^^^^^^^^^^^^^^^^^^^^^^^^^^^^^^^^^^^^^^^^^
    )
    ^
  File "/Users/elgiz/flyexpert/backend/.venv/lib/python3.13/site-packages/django/db/backends/utils.py", line 92, in _execute_with_wrappers
    return executor(sql, params, many, context)
  File "/Users/elgiz/flyexpert/backend/.venv/lib/python3.13/site-packages/django/db/backends/utils.py", line 100, in _execute
    with self.db.wrap_database_errors:
         ^^^^^^^^^^^^^^^^^^^^^^^^^^^^
  File "/Users/elgiz/flyexpert/backend/.venv/lib/python3.13/site-packages/django/db/utils.py", line 91, in __exit__
    raise dj_exc_value.with_traceback(traceback) from exc_value
  File "/Users/elgiz/flyexpert/backend/.venv/lib/python3.13/site-packages/django/db/backends/utils.py", line 105, in _execute
    return self.cursor.execute(sql, params)
           ~~~~~~~~~~~~~~~~~~~^^^^^^^^^^^^^
  File "/Users/elgiz/flyexpert/backend/.venv/lib/python3.13/site-packages/django/db/backends/sqlite3/base.py", line 354, in execute
    return super().execute(query, params)
           ~~~~~~~~~~~~~~~^^^^^^^^^^^^^^^
django.db.utils.OperationalError: no such table: accounts_userprofile
ERROR 2025-03-01 15:56:11,893 basehttp "GET /admin/accounts/userprofile/ HTTP/1.1" 500 186574
ERROR 2025-03-01 17:40:22,285 log Internal Server Error: /api/accounts/register/
Traceback (most recent call last):
  File "/Users/elgiz/flyexpert/backend/.venv/lib/python3.13/site-packages/django/db/backends/utils.py", line 105, in _execute
    return self.cursor.execute(sql, params)
           ~~~~~~~~~~~~~~~~~~~^^^^^^^^^^^^^
  File "/Users/elgiz/flyexpert/backend/.venv/lib/python3.13/site-packages/django/db/backends/sqlite3/base.py", line 354, in execute
    return super().execute(query, params)
           ~~~~~~~~~~~~~~~^^^^^^^^^^^^^^^
sqlite3.IntegrityError: NOT NULL constraint failed: accounts_customuser.is_admin

The above exception was the direct cause of the following exception:

Traceback (most recent call last):
  File "/Users/elgiz/flyexpert/backend/.venv/lib/python3.13/site-packages/django/core/handlers/exception.py", line 55, in inner
    response = get_response(request)
  File "/Users/elgiz/flyexpert/backend/.venv/lib/python3.13/site-packages/django/core/handlers/base.py", line 197, in _get_response
    response = wrapped_callback(request, *callback_args, **callback_kwargs)
  File "/Users/elgiz/flyexpert/backend/.venv/lib/python3.13/site-packages/django/views/decorators/csrf.py", line 65, in _view_wrapper
    return view_func(request, *args, **kwargs)
  File "/Users/elgiz/flyexpert/backend/.venv/lib/python3.13/site-packages/django/views/generic/base.py", line 104, in view
    return self.dispatch(request, *args, **kwargs)
           ~~~~~~~~~~~~~^^^^^^^^^^^^^^^^^^^^^^^^^^
  File "/Users/elgiz/flyexpert/backend/.venv/lib/python3.13/site-packages/rest_framework/views.py", line 509, in dispatch
    response = self.handle_exception(exc)
  File "/Users/elgiz/flyexpert/backend/.venv/lib/python3.13/site-packages/rest_framework/views.py", line 469, in handle_exception
    self.raise_uncaught_exception(exc)
    ~~~~~~~~~~~~~~~~~~~~~~~~~~~~~^^^^^
  File "/Users/elgiz/flyexpert/backend/.venv/lib/python3.13/site-packages/rest_framework/views.py", line 480, in raise_uncaught_exception
    raise exc
  File "/Users/elgiz/flyexpert/backend/.venv/lib/python3.13/site-packages/rest_framework/views.py", line 506, in dispatch
    response = handler(request, *args, **kwargs)
  File "/Users/elgiz/flyexpert/backend/backend/accounts/views.py", line 34, in post
    user = serializer.save()
  File "/Users/elgiz/flyexpert/backend/.venv/lib/python3.13/site-packages/rest_framework/serializers.py", line 208, in save
    self.instance = self.create(validated_data)
                    ~~~~~~~~~~~^^^^^^^^^^^^^^^^
  File "/Users/elgiz/flyexpert/backend/backend/accounts/serializers.py", line 29, in create
    user.save()  # ✅ İstifadəçini bazaya əlavə edir
    ~~~~~~~~~^^
  File "/Users/elgiz/flyexpert/backend/.venv/lib/python3.13/site-packages/django/contrib/auth/base_user.py", line 62, in save
    super().save(*args, **kwargs)
    ~~~~~~~~~~~~^^^^^^^^^^^^^^^^^
  File "/Users/elgiz/flyexpert/backend/.venv/lib/python3.13/site-packages/django/db/models/base.py", line 892, in save
    self.save_base(
    ~~~~~~~~~~~~~~^
        using=using,
        ^^^^^^^^^^^^
    ...<2 lines>...
        update_fields=update_fields,
        ^^^^^^^^^^^^^^^^^^^^^^^^^^^^
    )
    ^
  File "/Users/elgiz/flyexpert/backend/.venv/lib/python3.13/site-packages/django/db/models/base.py", line 998, in save_base
    updated = self._save_table(
        raw,
    ...<4 lines>...
        update_fields,
    )
  File "/Users/elgiz/flyexpert/backend/.venv/lib/python3.13/site-packages/django/db/models/base.py", line 1161, in _save_table
    results = self._do_insert(
        cls._base_manager, using, fields, returning_fields, raw
    )
  File "/Users/elgiz/flyexpert/backend/.venv/lib/python3.13/site-packages/django/db/models/base.py", line 1202, in _do_insert
    return manager._insert(
           ~~~~~~~~~~~~~~~^
        [self],
        ^^^^^^^
    ...<3 lines>...
        raw=raw,
        ^^^^^^^^
    )
    ^
  File "/Users/elgiz/flyexpert/backend/.venv/lib/python3.13/site-packages/django/db/models/manager.py", line 87, in manager_method
    return getattr(self.get_queryset(), name)(*args, **kwargs)
           ~~~~~~~~~~~~~~~~~~~~~~~~~~~~~~~~~~^^^^^^^^^^^^^^^^^
  File "/Users/elgiz/flyexpert/backend/.venv/lib/python3.13/site-packages/django/db/models/query.py", line 1847, in _insert
    return query.get_compiler(using=using).execute_sql(returning_fields)
           ~~~~~~~~~~~~~~~~~~~~~~~~~~~~~~~~~~~~~~~~~~~^^^^^^^^^^^^^^^^^^
  File "/Users/elgiz/flyexpert/backend/.venv/lib/python3.13/site-packages/django/db/models/sql/compiler.py", line 1836, in execute_sql
    cursor.execute(sql, params)
    ~~~~~~~~~~~~~~^^^^^^^^^^^^^
  File "/Users/elgiz/flyexpert/backend/.venv/lib/python3.13/site-packages/django/db/backends/utils.py", line 122, in execute
    return super().execute(sql, params)
           ~~~~~~~~~~~~~~~^^^^^^^^^^^^^
  File "/Users/elgiz/flyexpert/backend/.venv/lib/python3.13/site-packages/django/db/backends/utils.py", line 79, in execute
    return self._execute_with_wrappers(
           ~~~~~~~~~~~~~~~~~~~~~~~~~~~^
        sql, params, many=False, executor=self._execute
        ^^^^^^^^^^^^^^^^^^^^^^^^^^^^^^^^^^^^^^^^^^^^^^^
    )
    ^
  File "/Users/elgiz/flyexpert/backend/.venv/lib/python3.13/site-packages/django/db/backends/utils.py", line 92, in _execute_with_wrappers
    return executor(sql, params, many, context)
  File "/Users/elgiz/flyexpert/backend/.venv/lib/python3.13/site-packages/django/db/backends/utils.py", line 100, in _execute
    with self.db.wrap_database_errors:
         ^^^^^^^^^^^^^^^^^^^^^^^^^^^^
  File "/Users/elgiz/flyexpert/backend/.venv/lib/python3.13/site-packages/django/db/utils.py", line 91, in __exit__
    raise dj_exc_value.with_traceback(traceback) from exc_value
  File "/Users/elgiz/flyexpert/backend/.venv/lib/python3.13/site-packages/django/db/backends/utils.py", line 105, in _execute
    return self.cursor.execute(sql, params)
           ~~~~~~~~~~~~~~~~~~~^^^^^^^^^^^^^
  File "/Users/elgiz/flyexpert/backend/.venv/lib/python3.13/site-packages/django/db/backends/sqlite3/base.py", line 354, in execute
    return super().execute(query, params)
           ~~~~~~~~~~~~~~~^^^^^^^^^^^^^^^
django.db.utils.IntegrityError: NOT NULL constraint failed: accounts_customuser.is_admin
ERROR 2025-03-01 17:40:22,304 basehttp "POST /api/accounts/register/ HTTP/1.1" 500 185945
ERROR 2025-03-01 17:40:37,105 log Internal Server Error: /admin/accounts/customuser/
Traceback (most recent call last):
  File "/Users/elgiz/flyexpert/backend/.venv/lib/python3.13/site-packages/django/db/models/options.py", line 676, in get_field
    return self.fields_map[field_name]
           ~~~~~~~~~~~~~~~^^^^^^^^^^^^
KeyError: 'bonus'

During handling of the above exception, another exception occurred:

Traceback (most recent call last):
  File "/Users/elgiz/flyexpert/backend/.venv/lib/python3.13/site-packages/django/contrib/admin/utils.py", line 290, in lookup_field
    f = _get_non_gfk_field(opts, name)
  File "/Users/elgiz/flyexpert/backend/.venv/lib/python3.13/site-packages/django/contrib/admin/utils.py", line 330, in _get_non_gfk_field
    field = opts.get_field(name)
  File "/Users/elgiz/flyexpert/backend/.venv/lib/python3.13/site-packages/django/db/models/options.py", line 678, in get_field
    raise FieldDoesNotExist(
        "%s has no field named '%s'" % (self.object_name, field_name)
    )
django.core.exceptions.FieldDoesNotExist: CustomUser has no field named 'bonus'

During handling of the above exception, another exception occurred:

Traceback (most recent call last):
  File "/Users/elgiz/flyexpert/backend/.venv/lib/python3.13/site-packages/django/db/models/fields/related_descriptors.py", line 512, in __get__
    rel_obj = self.related.get_cached_value(instance)
  File "/Users/elgiz/flyexpert/backend/.venv/lib/python3.13/site-packages/django/db/models/fields/mixins.py", line 37, in get_cached_value
    return instance._state.fields_cache[self.cache_name]
           ~~~~~~~~~~~~~~~~~~~~~~~~~~~~^^^^^^^^^^^^^^^^^
KeyError: 'userprofile'

During handling of the above exception, another exception occurred:

Traceback (most recent call last):
  File "/Users/elgiz/flyexpert/backend/.venv/lib/python3.13/site-packages/django/db/backends/utils.py", line 105, in _execute
    return self.cursor.execute(sql, params)
           ~~~~~~~~~~~~~~~~~~~^^^^^^^^^^^^^
  File "/Users/elgiz/flyexpert/backend/.venv/lib/python3.13/site-packages/django/db/backends/sqlite3/base.py", line 354, in execute
    return super().execute(query, params)
           ~~~~~~~~~~~~~~~^^^^^^^^^^^^^^^
sqlite3.OperationalError: no such table: accounts_userprofile

The above exception was the direct cause of the following exception:

Traceback (most recent call last):
  File "/Users/elgiz/flyexpert/backend/.venv/lib/python3.13/site-packages/django/core/handlers/exception.py", line 55, in inner
    response = get_response(request)
  File "/Users/elgiz/flyexpert/backend/.venv/lib/python3.13/site-packages/django/core/handlers/base.py", line 220, in _get_response
    response = response.render()
  File "/Users/elgiz/flyexpert/backend/.venv/lib/python3.13/site-packages/django/template/response.py", line 114, in render
    self.content = self.rendered_content
                   ^^^^^^^^^^^^^^^^^^^^^
  File "/Users/elgiz/flyexpert/backend/.venv/lib/python3.13/site-packages/django/template/response.py", line 92, in rendered_content
    return template.render(context, self._request)
           ~~~~~~~~~~~~~~~^^^^^^^^^^^^^^^^^^^^^^^^
  File "/Users/elgiz/flyexpert/backend/.venv/lib/python3.13/site-packages/django/template/backends/django.py", line 107, in render
    return self.template.render(context)
           ~~~~~~~~~~~~~~~~~~~~^^^^^^^^^
  File "/Users/elgiz/flyexpert/backend/.venv/lib/python3.13/site-packages/django/template/base.py", line 171, in render
    return self._render(context)
           ~~~~~~~~~~~~^^^^^^^^^
  File "/Users/elgiz/flyexpert/backend/.venv/lib/python3.13/site-packages/django/template/base.py", line 163, in _render
    return self.nodelist.render(context)
           ~~~~~~~~~~~~~~~~~~~~^^^^^^^^^
  File "/Users/elgiz/flyexpert/backend/.venv/lib/python3.13/site-packages/django/template/base.py", line 1008, in render
    return SafeString("".join([node.render_annotated(context) for node in self]))
                               ~~~~~~~~~~~~~~~~~~~~~^^^^^^^^^
  File "/Users/elgiz/flyexpert/backend/.venv/lib/python3.13/site-packages/django/template/base.py", line 969, in render_annotated
    return self.render(context)
           ~~~~~~~~~~~^^^^^^^^^
  File "/Users/elgiz/flyexpert/backend/.venv/lib/python3.13/site-packages/django/template/loader_tags.py", line 159, in render
    return compiled_parent._render(context)
           ~~~~~~~~~~~~~~~~~~~~~~~^^^^^^^^^
  File "/Users/elgiz/flyexpert/backend/.venv/lib/python3.13/site-packages/django/template/base.py", line 163, in _render
    return self.nodelist.render(context)
           ~~~~~~~~~~~~~~~~~~~~^^^^^^^^^
  File "/Users/elgiz/flyexpert/backend/.venv/lib/python3.13/site-packages/django/template/base.py", line 1008, in render
    return SafeString("".join([node.render_annotated(context) for node in self]))
                               ~~~~~~~~~~~~~~~~~~~~~^^^^^^^^^
  File "/Users/elgiz/flyexpert/backend/.venv/lib/python3.13/site-packages/django/template/base.py", line 969, in render_annotated
    return self.render(context)
           ~~~~~~~~~~~^^^^^^^^^
  File "/Users/elgiz/flyexpert/backend/.venv/lib/python3.13/site-packages/django/template/loader_tags.py", line 159, in render
    return compiled_parent._render(context)
           ~~~~~~~~~~~~~~~~~~~~~~~^^^^^^^^^
  File "/Users/elgiz/flyexpert/backend/.venv/lib/python3.13/site-packages/django/template/base.py", line 163, in _render
    return self.nodelist.render(context)
           ~~~~~~~~~~~~~~~~~~~~^^^^^^^^^
  File "/Users/elgiz/flyexpert/backend/.venv/lib/python3.13/site-packages/django/template/base.py", line 1008, in render
    return SafeString("".join([node.render_annotated(context) for node in self]))
                               ~~~~~~~~~~~~~~~~~~~~~^^^^^^^^^
  File "/Users/elgiz/flyexpert/backend/.venv/lib/python3.13/site-packages/django/template/base.py", line 969, in render_annotated
    return self.render(context)
           ~~~~~~~~~~~^^^^^^^^^
  File "/Users/elgiz/flyexpert/backend/.venv/lib/python3.13/site-packages/django/template/loader_tags.py", line 65, in render
    result = block.nodelist.render(context)
  File "/Users/elgiz/flyexpert/backend/.venv/lib/python3.13/site-packages/django/template/base.py", line 1008, in render
    return SafeString("".join([node.render_annotated(context) for node in self]))
                               ~~~~~~~~~~~~~~~~~~~~~^^^^^^^^^
  File "/Users/elgiz/flyexpert/backend/.venv/lib/python3.13/site-packages/django/template/base.py", line 969, in render_annotated
    return self.render(context)
           ~~~~~~~~~~~^^^^^^^^^
  File "/Users/elgiz/flyexpert/backend/.venv/lib/python3.13/site-packages/django/template/loader_tags.py", line 65, in render
    result = block.nodelist.render(context)
  File "/Users/elgiz/flyexpert/backend/.venv/lib/python3.13/site-packages/django/template/base.py", line 1008, in render
    return SafeString("".join([node.render_annotated(context) for node in self]))
                               ~~~~~~~~~~~~~~~~~~~~~^^^^^^^^^
  File "/Users/elgiz/flyexpert/backend/.venv/lib/python3.13/site-packages/django/template/base.py", line 969, in render_annotated
    return self.render(context)
           ~~~~~~~~~~~^^^^^^^^^
  File "/Users/elgiz/flyexpert/backend/.venv/lib/python3.13/site-packages/django/contrib/admin/templatetags/base.py", line 45, in render
    return super().render(context)
           ~~~~~~~~~~~~~~^^^^^^^^^
  File "/Users/elgiz/flyexpert/backend/.venv/lib/python3.13/site-packages/django/template/library.py", line 258, in render
    _dict = self.func(*resolved_args, **resolved_kwargs)
  File "/Users/elgiz/flyexpert/backend/.venv/lib/python3.13/site-packages/django/contrib/admin/templatetags/admin_list.py", line 346, in result_list
    "results": list(results(cl)),
               ~~~~^^^^^^^^^^^^^
  File "/Users/elgiz/flyexpert/backend/.venv/lib/python3.13/site-packages/django/contrib/admin/templatetags/admin_list.py", line 322, in results
    yield ResultList(None, items_for_result(cl, res, None))
          ~~~~~~~~~~^^^^^^^^^^^^^^^^^^^^^^^^^^^^^^^^^^^^^^^
  File "/Users/elgiz/flyexpert/backend/.venv/lib/python3.13/site-packages/django/contrib/admin/templatetags/admin_list.py", line 313, in __init__
    super().__init__(*items)
    ~~~~~~~~~~~~~~~~^^^^^^^^
  File "/Users/elgiz/flyexpert/backend/.venv/lib/python3.13/site-packages/django/contrib/admin/templatetags/admin_list.py", line 218, in items_for_result
    f, attr, value = lookup_field(field_name, result, cl.model_admin)
                     ~~~~~~~~~~~~^^^^^^^^^^^^^^^^^^^^^^^^^^^^^^^^^^^^
  File "/Users/elgiz/flyexpert/backend/.venv/lib/python3.13/site-packages/django/contrib/admin/utils.py", line 299, in lookup_field
    value = attr(obj)
  File "/Users/elgiz/flyexpert/backend/backend/accounts/admin.py", line 19, in bonus
    return obj.userprofile.bonus  # `UserProfile` modelindən bonus məlumatını qaytarır
           ^^^^^^^^^^^^^^^
  File "/Users/elgiz/flyexpert/backend/.venv/lib/python3.13/site-packages/django/db/models/fields/related_descriptors.py", line 520, in __get__
    rel_obj = self.get_queryset(instance=instance).get(**filter_args)
  File "/Users/elgiz/flyexpert/backend/.venv/lib/python3.13/site-packages/django/db/models/query.py", line 645, in get
    num = len(clone)
  File "/Users/elgiz/flyexpert/backend/.venv/lib/python3.13/site-packages/django/db/models/query.py", line 382, in __len__
    self._fetch_all()
    ~~~~~~~~~~~~~~~^^
  File "/Users/elgiz/flyexpert/backend/.venv/lib/python3.13/site-packages/django/db/models/query.py", line 1928, in _fetch_all
    self._result_cache = list(self._iterable_class(self))
                         ~~~~^^^^^^^^^^^^^^^^^^^^^^^^^^^^
  File "/Users/elgiz/flyexpert/backend/.venv/lib/python3.13/site-packages/django/db/models/query.py", line 91, in __iter__
    results = compiler.execute_sql(
        chunked_fetch=self.chunked_fetch, chunk_size=self.chunk_size
    )
  File "/Users/elgiz/flyexpert/backend/.venv/lib/python3.13/site-packages/django/db/models/sql/compiler.py", line 1574, in execute_sql
    cursor.execute(sql, params)
    ~~~~~~~~~~~~~~^^^^^^^^^^^^^
  File "/Users/elgiz/flyexpert/backend/.venv/lib/python3.13/site-packages/django/db/backends/utils.py", line 122, in execute
    return super().execute(sql, params)
           ~~~~~~~~~~~~~~~^^^^^^^^^^^^^
  File "/Users/elgiz/flyexpert/backend/.venv/lib/python3.13/site-packages/django/db/backends/utils.py", line 79, in execute
    return self._execute_with_wrappers(
           ~~~~~~~~~~~~~~~~~~~~~~~~~~~^
        sql, params, many=False, executor=self._execute
        ^^^^^^^^^^^^^^^^^^^^^^^^^^^^^^^^^^^^^^^^^^^^^^^
    )
    ^
  File "/Users/elgiz/flyexpert/backend/.venv/lib/python3.13/site-packages/django/db/backends/utils.py", line 92, in _execute_with_wrappers
    return executor(sql, params, many, context)
  File "/Users/elgiz/flyexpert/backend/.venv/lib/python3.13/site-packages/django/db/backends/utils.py", line 100, in _execute
    with self.db.wrap_database_errors:
         ^^^^^^^^^^^^^^^^^^^^^^^^^^^^
  File "/Users/elgiz/flyexpert/backend/.venv/lib/python3.13/site-packages/django/db/utils.py", line 91, in __exit__
    raise dj_exc_value.with_traceback(traceback) from exc_value
  File "/Users/elgiz/flyexpert/backend/.venv/lib/python3.13/site-packages/django/db/backends/utils.py", line 105, in _execute
    return self.cursor.execute(sql, params)
           ~~~~~~~~~~~~~~~~~~~^^^^^^^^^^^^^
  File "/Users/elgiz/flyexpert/backend/.venv/lib/python3.13/site-packages/django/db/backends/sqlite3/base.py", line 354, in execute
    return super().execute(query, params)
           ~~~~~~~~~~~~~~~^^^^^^^^^^^^^^^
django.db.utils.OperationalError: no such table: accounts_userprofile
ERROR 2025-03-01 17:40:37,127 basehttp "GET /admin/accounts/customuser/ HTTP/1.1" 500 453958
ERROR 2025-03-01 17:40:42,355 log Internal Server Error: /admin/accounts/customuser/
Traceback (most recent call last):
  File "/Users/elgiz/flyexpert/backend/.venv/lib/python3.13/site-packages/django/db/models/options.py", line 676, in get_field
    return self.fields_map[field_name]
           ~~~~~~~~~~~~~~~^^^^^^^^^^^^
KeyError: 'bonus'

During handling of the above exception, another exception occurred:

Traceback (most recent call last):
  File "/Users/elgiz/flyexpert/backend/.venv/lib/python3.13/site-packages/django/contrib/admin/utils.py", line 290, in lookup_field
    f = _get_non_gfk_field(opts, name)
  File "/Users/elgiz/flyexpert/backend/.venv/lib/python3.13/site-packages/django/contrib/admin/utils.py", line 330, in _get_non_gfk_field
    field = opts.get_field(name)
  File "/Users/elgiz/flyexpert/backend/.venv/lib/python3.13/site-packages/django/db/models/options.py", line 678, in get_field
    raise FieldDoesNotExist(
        "%s has no field named '%s'" % (self.object_name, field_name)
    )
django.core.exceptions.FieldDoesNotExist: CustomUser has no field named 'bonus'

During handling of the above exception, another exception occurred:

Traceback (most recent call last):
  File "/Users/elgiz/flyexpert/backend/.venv/lib/python3.13/site-packages/django/db/models/fields/related_descriptors.py", line 512, in __get__
    rel_obj = self.related.get_cached_value(instance)
  File "/Users/elgiz/flyexpert/backend/.venv/lib/python3.13/site-packages/django/db/models/fields/mixins.py", line 37, in get_cached_value
    return instance._state.fields_cache[self.cache_name]
           ~~~~~~~~~~~~~~~~~~~~~~~~~~~~^^^^^^^^^^^^^^^^^
KeyError: 'userprofile'

During handling of the above exception, another exception occurred:

Traceback (most recent call last):
  File "/Users/elgiz/flyexpert/backend/.venv/lib/python3.13/site-packages/django/db/backends/utils.py", line 105, in _execute
    return self.cursor.execute(sql, params)
           ~~~~~~~~~~~~~~~~~~~^^^^^^^^^^^^^
  File "/Users/elgiz/flyexpert/backend/.venv/lib/python3.13/site-packages/django/db/backends/sqlite3/base.py", line 354, in execute
    return super().execute(query, params)
           ~~~~~~~~~~~~~~~^^^^^^^^^^^^^^^
sqlite3.OperationalError: no such table: accounts_userprofile

The above exception was the direct cause of the following exception:

Traceback (most recent call last):
  File "/Users/elgiz/flyexpert/backend/.venv/lib/python3.13/site-packages/django/core/handlers/exception.py", line 55, in inner
    response = get_response(request)
  File "/Users/elgiz/flyexpert/backend/.venv/lib/python3.13/site-packages/django/core/handlers/base.py", line 220, in _get_response
    response = response.render()
  File "/Users/elgiz/flyexpert/backend/.venv/lib/python3.13/site-packages/django/template/response.py", line 114, in render
    self.content = self.rendered_content
                   ^^^^^^^^^^^^^^^^^^^^^
  File "/Users/elgiz/flyexpert/backend/.venv/lib/python3.13/site-packages/django/template/response.py", line 92, in rendered_content
    return template.render(context, self._request)
           ~~~~~~~~~~~~~~~^^^^^^^^^^^^^^^^^^^^^^^^
  File "/Users/elgiz/flyexpert/backend/.venv/lib/python3.13/site-packages/django/template/backends/django.py", line 107, in render
    return self.template.render(context)
           ~~~~~~~~~~~~~~~~~~~~^^^^^^^^^
  File "/Users/elgiz/flyexpert/backend/.venv/lib/python3.13/site-packages/django/template/base.py", line 171, in render
    return self._render(context)
           ~~~~~~~~~~~~^^^^^^^^^
  File "/Users/elgiz/flyexpert/backend/.venv/lib/python3.13/site-packages/django/template/base.py", line 163, in _render
    return self.nodelist.render(context)
           ~~~~~~~~~~~~~~~~~~~~^^^^^^^^^
  File "/Users/elgiz/flyexpert/backend/.venv/lib/python3.13/site-packages/django/template/base.py", line 1008, in render
    return SafeString("".join([node.render_annotated(context) for node in self]))
                               ~~~~~~~~~~~~~~~~~~~~~^^^^^^^^^
  File "/Users/elgiz/flyexpert/backend/.venv/lib/python3.13/site-packages/django/template/base.py", line 969, in render_annotated
    return self.render(context)
           ~~~~~~~~~~~^^^^^^^^^
  File "/Users/elgiz/flyexpert/backend/.venv/lib/python3.13/site-packages/django/template/loader_tags.py", line 159, in render
    return compiled_parent._render(context)
           ~~~~~~~~~~~~~~~~~~~~~~~^^^^^^^^^
  File "/Users/elgiz/flyexpert/backend/.venv/lib/python3.13/site-packages/django/template/base.py", line 163, in _render
    return self.nodelist.render(context)
           ~~~~~~~~~~~~~~~~~~~~^^^^^^^^^
  File "/Users/elgiz/flyexpert/backend/.venv/lib/python3.13/site-packages/django/template/base.py", line 1008, in render
    return SafeString("".join([node.render_annotated(context) for node in self]))
                               ~~~~~~~~~~~~~~~~~~~~~^^^^^^^^^
  File "/Users/elgiz/flyexpert/backend/.venv/lib/python3.13/site-packages/django/template/base.py", line 969, in render_annotated
    return self.render(context)
           ~~~~~~~~~~~^^^^^^^^^
  File "/Users/elgiz/flyexpert/backend/.venv/lib/python3.13/site-packages/django/template/loader_tags.py", line 159, in render
    return compiled_parent._render(context)
           ~~~~~~~~~~~~~~~~~~~~~~~^^^^^^^^^
  File "/Users/elgiz/flyexpert/backend/.venv/lib/python3.13/site-packages/django/template/base.py", line 163, in _render
    return self.nodelist.render(context)
           ~~~~~~~~~~~~~~~~~~~~^^^^^^^^^
  File "/Users/elgiz/flyexpert/backend/.venv/lib/python3.13/site-packages/django/template/base.py", line 1008, in render
    return SafeString("".join([node.render_annotated(context) for node in self]))
                               ~~~~~~~~~~~~~~~~~~~~~^^^^^^^^^
  File "/Users/elgiz/flyexpert/backend/.venv/lib/python3.13/site-packages/django/template/base.py", line 969, in render_annotated
    return self.render(context)
           ~~~~~~~~~~~^^^^^^^^^
  File "/Users/elgiz/flyexpert/backend/.venv/lib/python3.13/site-packages/django/template/loader_tags.py", line 65, in render
    result = block.nodelist.render(context)
  File "/Users/elgiz/flyexpert/backend/.venv/lib/python3.13/site-packages/django/template/base.py", line 1008, in render
    return SafeString("".join([node.render_annotated(context) for node in self]))
                               ~~~~~~~~~~~~~~~~~~~~~^^^^^^^^^
  File "/Users/elgiz/flyexpert/backend/.venv/lib/python3.13/site-packages/django/template/base.py", line 969, in render_annotated
    return self.render(context)
           ~~~~~~~~~~~^^^^^^^^^
  File "/Users/elgiz/flyexpert/backend/.venv/lib/python3.13/site-packages/django/template/loader_tags.py", line 65, in render
    result = block.nodelist.render(context)
  File "/Users/elgiz/flyexpert/backend/.venv/lib/python3.13/site-packages/django/template/base.py", line 1008, in render
    return SafeString("".join([node.render_annotated(context) for node in self]))
                               ~~~~~~~~~~~~~~~~~~~~~^^^^^^^^^
  File "/Users/elgiz/flyexpert/backend/.venv/lib/python3.13/site-packages/django/template/base.py", line 969, in render_annotated
    return self.render(context)
           ~~~~~~~~~~~^^^^^^^^^
  File "/Users/elgiz/flyexpert/backend/.venv/lib/python3.13/site-packages/django/contrib/admin/templatetags/base.py", line 45, in render
    return super().render(context)
           ~~~~~~~~~~~~~~^^^^^^^^^
  File "/Users/elgiz/flyexpert/backend/.venv/lib/python3.13/site-packages/django/template/library.py", line 258, in render
    _dict = self.func(*resolved_args, **resolved_kwargs)
  File "/Users/elgiz/flyexpert/backend/.venv/lib/python3.13/site-packages/django/contrib/admin/templatetags/admin_list.py", line 346, in result_list
    "results": list(results(cl)),
               ~~~~^^^^^^^^^^^^^
  File "/Users/elgiz/flyexpert/backend/.venv/lib/python3.13/site-packages/django/contrib/admin/templatetags/admin_list.py", line 322, in results
    yield ResultList(None, items_for_result(cl, res, None))
          ~~~~~~~~~~^^^^^^^^^^^^^^^^^^^^^^^^^^^^^^^^^^^^^^^
  File "/Users/elgiz/flyexpert/backend/.venv/lib/python3.13/site-packages/django/contrib/admin/templatetags/admin_list.py", line 313, in __init__
    super().__init__(*items)
    ~~~~~~~~~~~~~~~~^^^^^^^^
  File "/Users/elgiz/flyexpert/backend/.venv/lib/python3.13/site-packages/django/contrib/admin/templatetags/admin_list.py", line 218, in items_for_result
    f, attr, value = lookup_field(field_name, result, cl.model_admin)
                     ~~~~~~~~~~~~^^^^^^^^^^^^^^^^^^^^^^^^^^^^^^^^^^^^
  File "/Users/elgiz/flyexpert/backend/.venv/lib/python3.13/site-packages/django/contrib/admin/utils.py", line 299, in lookup_field
    value = attr(obj)
  File "/Users/elgiz/flyexpert/backend/backend/accounts/admin.py", line 19, in bonus
    return obj.userprofile.bonus  # `UserProfile` modelindən bonus məlumatını qaytarır
           ^^^^^^^^^^^^^^^
  File "/Users/elgiz/flyexpert/backend/.venv/lib/python3.13/site-packages/django/db/models/fields/related_descriptors.py", line 520, in __get__
    rel_obj = self.get_queryset(instance=instance).get(**filter_args)
  File "/Users/elgiz/flyexpert/backend/.venv/lib/python3.13/site-packages/django/db/models/query.py", line 645, in get
    num = len(clone)
  File "/Users/elgiz/flyexpert/backend/.venv/lib/python3.13/site-packages/django/db/models/query.py", line 382, in __len__
    self._fetch_all()
    ~~~~~~~~~~~~~~~^^
  File "/Users/elgiz/flyexpert/backend/.venv/lib/python3.13/site-packages/django/db/models/query.py", line 1928, in _fetch_all
    self._result_cache = list(self._iterable_class(self))
                         ~~~~^^^^^^^^^^^^^^^^^^^^^^^^^^^^
  File "/Users/elgiz/flyexpert/backend/.venv/lib/python3.13/site-packages/django/db/models/query.py", line 91, in __iter__
    results = compiler.execute_sql(
        chunked_fetch=self.chunked_fetch, chunk_size=self.chunk_size
    )
  File "/Users/elgiz/flyexpert/backend/.venv/lib/python3.13/site-packages/django/db/models/sql/compiler.py", line 1574, in execute_sql
    cursor.execute(sql, params)
    ~~~~~~~~~~~~~~^^^^^^^^^^^^^
  File "/Users/elgiz/flyexpert/backend/.venv/lib/python3.13/site-packages/django/db/backends/utils.py", line 122, in execute
    return super().execute(sql, params)
           ~~~~~~~~~~~~~~~^^^^^^^^^^^^^
  File "/Users/elgiz/flyexpert/backend/.venv/lib/python3.13/site-packages/django/db/backends/utils.py", line 79, in execute
    return self._execute_with_wrappers(
           ~~~~~~~~~~~~~~~~~~~~~~~~~~~^
        sql, params, many=False, executor=self._execute
        ^^^^^^^^^^^^^^^^^^^^^^^^^^^^^^^^^^^^^^^^^^^^^^^
    )
    ^
  File "/Users/elgiz/flyexpert/backend/.venv/lib/python3.13/site-packages/django/db/backends/utils.py", line 92, in _execute_with_wrappers
    return executor(sql, params, many, context)
  File "/Users/elgiz/flyexpert/backend/.venv/lib/python3.13/site-packages/django/db/backends/utils.py", line 100, in _execute
    with self.db.wrap_database_errors:
         ^^^^^^^^^^^^^^^^^^^^^^^^^^^^
  File "/Users/elgiz/flyexpert/backend/.venv/lib/python3.13/site-packages/django/db/utils.py", line 91, in __exit__
    raise dj_exc_value.with_traceback(traceback) from exc_value
  File "/Users/elgiz/flyexpert/backend/.venv/lib/python3.13/site-packages/django/db/backends/utils.py", line 105, in _execute
    return self.cursor.execute(sql, params)
           ~~~~~~~~~~~~~~~~~~~^^^^^^^^^^^^^
  File "/Users/elgiz/flyexpert/backend/.venv/lib/python3.13/site-packages/django/db/backends/sqlite3/base.py", line 354, in execute
    return super().execute(query, params)
           ~~~~~~~~~~~~~~~^^^^^^^^^^^^^^^
django.db.utils.OperationalError: no such table: accounts_userprofile
ERROR 2025-03-01 17:40:42,374 basehttp "GET /admin/accounts/customuser/ HTTP/1.1" 500 453958
ERROR 2025-03-01 17:40:49,872 log Internal Server Error: /admin/accounts/userprofile/
Traceback (most recent call last):
  File "/Users/elgiz/flyexpert/backend/.venv/lib/python3.13/site-packages/django/db/backends/utils.py", line 105, in _execute
    return self.cursor.execute(sql, params)
           ~~~~~~~~~~~~~~~~~~~^^^^^^^^^^^^^
  File "/Users/elgiz/flyexpert/backend/.venv/lib/python3.13/site-packages/django/db/backends/sqlite3/base.py", line 354, in execute
    return super().execute(query, params)
           ~~~~~~~~~~~~~~~^^^^^^^^^^^^^^^
sqlite3.OperationalError: no such table: accounts_userprofile

The above exception was the direct cause of the following exception:

Traceback (most recent call last):
  File "/Users/elgiz/flyexpert/backend/.venv/lib/python3.13/site-packages/django/core/handlers/exception.py", line 55, in inner
    response = get_response(request)
  File "/Users/elgiz/flyexpert/backend/.venv/lib/python3.13/site-packages/django/core/handlers/base.py", line 197, in _get_response
    response = wrapped_callback(request, *callback_args, **callback_kwargs)
  File "/Users/elgiz/flyexpert/backend/.venv/lib/python3.13/site-packages/django/contrib/admin/options.py", line 718, in wrapper
    return self.admin_site.admin_view(view)(*args, **kwargs)
           ~~~~~~~~~~~~~~~~~~~~~~~~~~~~~~~~^^^^^^^^^^^^^^^^^
  File "/Users/elgiz/flyexpert/backend/.venv/lib/python3.13/site-packages/django/utils/decorators.py", line 188, in _view_wrapper
    result = _process_exception(request, e)
  File "/Users/elgiz/flyexpert/backend/.venv/lib/python3.13/site-packages/django/utils/decorators.py", line 186, in _view_wrapper
    response = view_func(request, *args, **kwargs)
  File "/Users/elgiz/flyexpert/backend/.venv/lib/python3.13/site-packages/django/views/decorators/cache.py", line 80, in _view_wrapper
    response = view_func(request, *args, **kwargs)
  File "/Users/elgiz/flyexpert/backend/.venv/lib/python3.13/site-packages/django/contrib/admin/sites.py", line 241, in inner
    return view(request, *args, **kwargs)
  File "/Users/elgiz/flyexpert/backend/.venv/lib/python3.13/site-packages/django/utils/decorators.py", line 48, in _wrapper
    return bound_method(*args, **kwargs)
  File "/Users/elgiz/flyexpert/backend/.venv/lib/python3.13/site-packages/django/utils/decorators.py", line 188, in _view_wrapper
    result = _process_exception(request, e)
  File "/Users/elgiz/flyexpert/backend/.venv/lib/python3.13/site-packages/django/utils/decorators.py", line 186, in _view_wrapper
    response = view_func(request, *args, **kwargs)
  File "/Users/elgiz/flyexpert/backend/.venv/lib/python3.13/site-packages/django/contrib/admin/options.py", line 2001, in changelist_view
    cl = self.get_changelist_instance(request)
  File "/Users/elgiz/flyexpert/backend/.venv/lib/python3.13/site-packages/django/contrib/admin/options.py", line 866, in get_changelist_instance
    return ChangeList(
        request,
    ...<12 lines>...
        self.search_help_text,
    )
  File "/Users/elgiz/flyexpert/backend/.venv/lib/python3.13/site-packages/django/contrib/admin/views/main.py", line 146, in __init__
    self.get_results(request)
    ~~~~~~~~~~~~~~~~^^^^^^^^^
  File "/Users/elgiz/flyexpert/backend/.venv/lib/python3.13/site-packages/django/contrib/admin/views/main.py", line 313, in get_results
    result_count = paginator.count
                   ^^^^^^^^^^^^^^^
  File "/Users/elgiz/flyexpert/backend/.venv/lib/python3.13/site-packages/django/utils/functional.py", line 47, in __get__
    res = instance.__dict__[self.name] = self.func(instance)
                                         ~~~~~~~~~^^^^^^^^^^
  File "/Users/elgiz/flyexpert/backend/.venv/lib/python3.13/site-packages/django/core/paginator.py", line 110, in count
    return c()
  File "/Users/elgiz/flyexpert/backend/.venv/lib/python3.13/site-packages/django/db/models/query.py", line 620, in count
    return self.query.get_count(using=self.db)
           ~~~~~~~~~~~~~~~~~~~~^^^^^^^^^^^^^^^
  File "/Users/elgiz/flyexpert/backend/.venv/lib/python3.13/site-packages/django/db/models/sql/query.py", line 630, in get_count
    return obj.get_aggregation(using, {"__count": Count("*")})["__count"]
           ~~~~~~~~~~~~~~~~~~~^^^^^^^^^^^^^^^^^^^^^^^^^^^^^^^^
  File "/Users/elgiz/flyexpert/backend/.venv/lib/python3.13/site-packages/django/db/models/sql/query.py", line 616, in get_aggregation
    result = compiler.execute_sql(SINGLE)
  File "/Users/elgiz/flyexpert/backend/.venv/lib/python3.13/site-packages/django/db/models/sql/compiler.py", line 1574, in execute_sql
    cursor.execute(sql, params)
    ~~~~~~~~~~~~~~^^^^^^^^^^^^^
  File "/Users/elgiz/flyexpert/backend/.venv/lib/python3.13/site-packages/django/db/backends/utils.py", line 122, in execute
    return super().execute(sql, params)
           ~~~~~~~~~~~~~~~^^^^^^^^^^^^^
  File "/Users/elgiz/flyexpert/backend/.venv/lib/python3.13/site-packages/django/db/backends/utils.py", line 79, in execute
    return self._execute_with_wrappers(
           ~~~~~~~~~~~~~~~~~~~~~~~~~~~^
        sql, params, many=False, executor=self._execute
        ^^^^^^^^^^^^^^^^^^^^^^^^^^^^^^^^^^^^^^^^^^^^^^^
    )
    ^
  File "/Users/elgiz/flyexpert/backend/.venv/lib/python3.13/site-packages/django/db/backends/utils.py", line 92, in _execute_with_wrappers
    return executor(sql, params, many, context)
  File "/Users/elgiz/flyexpert/backend/.venv/lib/python3.13/site-packages/django/db/backends/utils.py", line 100, in _execute
    with self.db.wrap_database_errors:
         ^^^^^^^^^^^^^^^^^^^^^^^^^^^^
  File "/Users/elgiz/flyexpert/backend/.venv/lib/python3.13/site-packages/django/db/utils.py", line 91, in __exit__
    raise dj_exc_value.with_traceback(traceback) from exc_value
  File "/Users/elgiz/flyexpert/backend/.venv/lib/python3.13/site-packages/django/db/backends/utils.py", line 105, in _execute
    return self.cursor.execute(sql, params)
           ~~~~~~~~~~~~~~~~~~~^^^^^^^^^^^^^
  File "/Users/elgiz/flyexpert/backend/.venv/lib/python3.13/site-packages/django/db/backends/sqlite3/base.py", line 354, in execute
    return super().execute(query, params)
           ~~~~~~~~~~~~~~~^^^^^^^^^^^^^^^
django.db.utils.OperationalError: no such table: accounts_userprofile
ERROR 2025-03-01 17:40:49,889 basehttp "GET /admin/accounts/userprofile/ HTTP/1.1" 500 186415
ERROR 2025-03-01 17:40:57,162 log Internal Server Error: /admin/accounts/customuser/
Traceback (most recent call last):
  File "/Users/elgiz/flyexpert/backend/.venv/lib/python3.13/site-packages/django/db/models/options.py", line 676, in get_field
    return self.fields_map[field_name]
           ~~~~~~~~~~~~~~~^^^^^^^^^^^^
KeyError: 'bonus'

During handling of the above exception, another exception occurred:

Traceback (most recent call last):
  File "/Users/elgiz/flyexpert/backend/.venv/lib/python3.13/site-packages/django/contrib/admin/utils.py", line 290, in lookup_field
    f = _get_non_gfk_field(opts, name)
  File "/Users/elgiz/flyexpert/backend/.venv/lib/python3.13/site-packages/django/contrib/admin/utils.py", line 330, in _get_non_gfk_field
    field = opts.get_field(name)
  File "/Users/elgiz/flyexpert/backend/.venv/lib/python3.13/site-packages/django/db/models/options.py", line 678, in get_field
    raise FieldDoesNotExist(
        "%s has no field named '%s'" % (self.object_name, field_name)
    )
django.core.exceptions.FieldDoesNotExist: CustomUser has no field named 'bonus'

During handling of the above exception, another exception occurred:

Traceback (most recent call last):
  File "/Users/elgiz/flyexpert/backend/.venv/lib/python3.13/site-packages/django/db/models/fields/related_descriptors.py", line 512, in __get__
    rel_obj = self.related.get_cached_value(instance)
  File "/Users/elgiz/flyexpert/backend/.venv/lib/python3.13/site-packages/django/db/models/fields/mixins.py", line 37, in get_cached_value
    return instance._state.fields_cache[self.cache_name]
           ~~~~~~~~~~~~~~~~~~~~~~~~~~~~^^^^^^^^^^^^^^^^^
KeyError: 'userprofile'

During handling of the above exception, another exception occurred:

Traceback (most recent call last):
  File "/Users/elgiz/flyexpert/backend/.venv/lib/python3.13/site-packages/django/db/backends/utils.py", line 105, in _execute
    return self.cursor.execute(sql, params)
           ~~~~~~~~~~~~~~~~~~~^^^^^^^^^^^^^
  File "/Users/elgiz/flyexpert/backend/.venv/lib/python3.13/site-packages/django/db/backends/sqlite3/base.py", line 354, in execute
    return super().execute(query, params)
           ~~~~~~~~~~~~~~~^^^^^^^^^^^^^^^
sqlite3.OperationalError: no such table: accounts_userprofile

The above exception was the direct cause of the following exception:

Traceback (most recent call last):
  File "/Users/elgiz/flyexpert/backend/.venv/lib/python3.13/site-packages/django/core/handlers/exception.py", line 55, in inner
    response = get_response(request)
  File "/Users/elgiz/flyexpert/backend/.venv/lib/python3.13/site-packages/django/core/handlers/base.py", line 220, in _get_response
    response = response.render()
  File "/Users/elgiz/flyexpert/backend/.venv/lib/python3.13/site-packages/django/template/response.py", line 114, in render
    self.content = self.rendered_content
                   ^^^^^^^^^^^^^^^^^^^^^
  File "/Users/elgiz/flyexpert/backend/.venv/lib/python3.13/site-packages/django/template/response.py", line 92, in rendered_content
    return template.render(context, self._request)
           ~~~~~~~~~~~~~~~^^^^^^^^^^^^^^^^^^^^^^^^
  File "/Users/elgiz/flyexpert/backend/.venv/lib/python3.13/site-packages/django/template/backends/django.py", line 107, in render
    return self.template.render(context)
           ~~~~~~~~~~~~~~~~~~~~^^^^^^^^^
  File "/Users/elgiz/flyexpert/backend/.venv/lib/python3.13/site-packages/django/template/base.py", line 171, in render
    return self._render(context)
           ~~~~~~~~~~~~^^^^^^^^^
  File "/Users/elgiz/flyexpert/backend/.venv/lib/python3.13/site-packages/django/template/base.py", line 163, in _render
    return self.nodelist.render(context)
           ~~~~~~~~~~~~~~~~~~~~^^^^^^^^^
  File "/Users/elgiz/flyexpert/backend/.venv/lib/python3.13/site-packages/django/template/base.py", line 1008, in render
    return SafeString("".join([node.render_annotated(context) for node in self]))
                               ~~~~~~~~~~~~~~~~~~~~~^^^^^^^^^
  File "/Users/elgiz/flyexpert/backend/.venv/lib/python3.13/site-packages/django/template/base.py", line 969, in render_annotated
    return self.render(context)
           ~~~~~~~~~~~^^^^^^^^^
  File "/Users/elgiz/flyexpert/backend/.venv/lib/python3.13/site-packages/django/template/loader_tags.py", line 159, in render
    return compiled_parent._render(context)
           ~~~~~~~~~~~~~~~~~~~~~~~^^^^^^^^^
  File "/Users/elgiz/flyexpert/backend/.venv/lib/python3.13/site-packages/django/template/base.py", line 163, in _render
    return self.nodelist.render(context)
           ~~~~~~~~~~~~~~~~~~~~^^^^^^^^^
  File "/Users/elgiz/flyexpert/backend/.venv/lib/python3.13/site-packages/django/template/base.py", line 1008, in render
    return SafeString("".join([node.render_annotated(context) for node in self]))
                               ~~~~~~~~~~~~~~~~~~~~~^^^^^^^^^
  File "/Users/elgiz/flyexpert/backend/.venv/lib/python3.13/site-packages/django/template/base.py", line 969, in render_annotated
    return self.render(context)
           ~~~~~~~~~~~^^^^^^^^^
  File "/Users/elgiz/flyexpert/backend/.venv/lib/python3.13/site-packages/django/template/loader_tags.py", line 159, in render
    return compiled_parent._render(context)
           ~~~~~~~~~~~~~~~~~~~~~~~^^^^^^^^^
  File "/Users/elgiz/flyexpert/backend/.venv/lib/python3.13/site-packages/django/template/base.py", line 163, in _render
    return self.nodelist.render(context)
           ~~~~~~~~~~~~~~~~~~~~^^^^^^^^^
  File "/Users/elgiz/flyexpert/backend/.venv/lib/python3.13/site-packages/django/template/base.py", line 1008, in render
    return SafeString("".join([node.render_annotated(context) for node in self]))
                               ~~~~~~~~~~~~~~~~~~~~~^^^^^^^^^
  File "/Users/elgiz/flyexpert/backend/.venv/lib/python3.13/site-packages/django/template/base.py", line 969, in render_annotated
    return self.render(context)
           ~~~~~~~~~~~^^^^^^^^^
  File "/Users/elgiz/flyexpert/backend/.venv/lib/python3.13/site-packages/django/template/loader_tags.py", line 65, in render
    result = block.nodelist.render(context)
  File "/Users/elgiz/flyexpert/backend/.venv/lib/python3.13/site-packages/django/template/base.py", line 1008, in render
    return SafeString("".join([node.render_annotated(context) for node in self]))
                               ~~~~~~~~~~~~~~~~~~~~~^^^^^^^^^
  File "/Users/elgiz/flyexpert/backend/.venv/lib/python3.13/site-packages/django/template/base.py", line 969, in render_annotated
    return self.render(context)
           ~~~~~~~~~~~^^^^^^^^^
  File "/Users/elgiz/flyexpert/backend/.venv/lib/python3.13/site-packages/django/template/loader_tags.py", line 65, in render
    result = block.nodelist.render(context)
  File "/Users/elgiz/flyexpert/backend/.venv/lib/python3.13/site-packages/django/template/base.py", line 1008, in render
    return SafeString("".join([node.render_annotated(context) for node in self]))
                               ~~~~~~~~~~~~~~~~~~~~~^^^^^^^^^
  File "/Users/elgiz/flyexpert/backend/.venv/lib/python3.13/site-packages/django/template/base.py", line 969, in render_annotated
    return self.render(context)
           ~~~~~~~~~~~^^^^^^^^^
  File "/Users/elgiz/flyexpert/backend/.venv/lib/python3.13/site-packages/django/contrib/admin/templatetags/base.py", line 45, in render
    return super().render(context)
           ~~~~~~~~~~~~~~^^^^^^^^^
  File "/Users/elgiz/flyexpert/backend/.venv/lib/python3.13/site-packages/django/template/library.py", line 258, in render
    _dict = self.func(*resolved_args, **resolved_kwargs)
  File "/Users/elgiz/flyexpert/backend/.venv/lib/python3.13/site-packages/django/contrib/admin/templatetags/admin_list.py", line 346, in result_list
    "results": list(results(cl)),
               ~~~~^^^^^^^^^^^^^
  File "/Users/elgiz/flyexpert/backend/.venv/lib/python3.13/site-packages/django/contrib/admin/templatetags/admin_list.py", line 322, in results
    yield ResultList(None, items_for_result(cl, res, None))
          ~~~~~~~~~~^^^^^^^^^^^^^^^^^^^^^^^^^^^^^^^^^^^^^^^
  File "/Users/elgiz/flyexpert/backend/.venv/lib/python3.13/site-packages/django/contrib/admin/templatetags/admin_list.py", line 313, in __init__
    super().__init__(*items)
    ~~~~~~~~~~~~~~~~^^^^^^^^
  File "/Users/elgiz/flyexpert/backend/.venv/lib/python3.13/site-packages/django/contrib/admin/templatetags/admin_list.py", line 218, in items_for_result
    f, attr, value = lookup_field(field_name, result, cl.model_admin)
                     ~~~~~~~~~~~~^^^^^^^^^^^^^^^^^^^^^^^^^^^^^^^^^^^^
  File "/Users/elgiz/flyexpert/backend/.venv/lib/python3.13/site-packages/django/contrib/admin/utils.py", line 299, in lookup_field
    value = attr(obj)
  File "/Users/elgiz/flyexpert/backend/backend/accounts/admin.py", line 19, in bonus
    return obj.userprofile.bonus  # `UserProfile` modelindən bonus məlumatını qaytarır
           ^^^^^^^^^^^^^^^
  File "/Users/elgiz/flyexpert/backend/.venv/lib/python3.13/site-packages/django/db/models/fields/related_descriptors.py", line 520, in __get__
    rel_obj = self.get_queryset(instance=instance).get(**filter_args)
  File "/Users/elgiz/flyexpert/backend/.venv/lib/python3.13/site-packages/django/db/models/query.py", line 645, in get
    num = len(clone)
  File "/Users/elgiz/flyexpert/backend/.venv/lib/python3.13/site-packages/django/db/models/query.py", line 382, in __len__
    self._fetch_all()
    ~~~~~~~~~~~~~~~^^
  File "/Users/elgiz/flyexpert/backend/.venv/lib/python3.13/site-packages/django/db/models/query.py", line 1928, in _fetch_all
    self._result_cache = list(self._iterable_class(self))
                         ~~~~^^^^^^^^^^^^^^^^^^^^^^^^^^^^
  File "/Users/elgiz/flyexpert/backend/.venv/lib/python3.13/site-packages/django/db/models/query.py", line 91, in __iter__
    results = compiler.execute_sql(
        chunked_fetch=self.chunked_fetch, chunk_size=self.chunk_size
    )
  File "/Users/elgiz/flyexpert/backend/.venv/lib/python3.13/site-packages/django/db/models/sql/compiler.py", line 1574, in execute_sql
    cursor.execute(sql, params)
    ~~~~~~~~~~~~~~^^^^^^^^^^^^^
  File "/Users/elgiz/flyexpert/backend/.venv/lib/python3.13/site-packages/django/db/backends/utils.py", line 122, in execute
    return super().execute(sql, params)
           ~~~~~~~~~~~~~~~^^^^^^^^^^^^^
  File "/Users/elgiz/flyexpert/backend/.venv/lib/python3.13/site-packages/django/db/backends/utils.py", line 79, in execute
    return self._execute_with_wrappers(
           ~~~~~~~~~~~~~~~~~~~~~~~~~~~^
        sql, params, many=False, executor=self._execute
        ^^^^^^^^^^^^^^^^^^^^^^^^^^^^^^^^^^^^^^^^^^^^^^^
    )
    ^
  File "/Users/elgiz/flyexpert/backend/.venv/lib/python3.13/site-packages/django/db/backends/utils.py", line 92, in _execute_with_wrappers
    return executor(sql, params, many, context)
  File "/Users/elgiz/flyexpert/backend/.venv/lib/python3.13/site-packages/django/db/backends/utils.py", line 100, in _execute
    with self.db.wrap_database_errors:
         ^^^^^^^^^^^^^^^^^^^^^^^^^^^^
  File "/Users/elgiz/flyexpert/backend/.venv/lib/python3.13/site-packages/django/db/utils.py", line 91, in __exit__
    raise dj_exc_value.with_traceback(traceback) from exc_value
  File "/Users/elgiz/flyexpert/backend/.venv/lib/python3.13/site-packages/django/db/backends/utils.py", line 105, in _execute
    return self.cursor.execute(sql, params)
           ~~~~~~~~~~~~~~~~~~~^^^^^^^^^^^^^
  File "/Users/elgiz/flyexpert/backend/.venv/lib/python3.13/site-packages/django/db/backends/sqlite3/base.py", line 354, in execute
    return super().execute(query, params)
           ~~~~~~~~~~~~~~~^^^^^^^^^^^^^^^
django.db.utils.OperationalError: no such table: accounts_userprofile
ERROR 2025-03-01 17:40:57,180 basehttp "GET /admin/accounts/customuser/ HTTP/1.1" 500 453958
ERROR 2025-03-01 17:41:08,602 log Internal Server Error: /admin/accounts/customuser/
Traceback (most recent call last):
  File "/Users/elgiz/flyexpert/backend/.venv/lib/python3.13/site-packages/django/db/models/options.py", line 676, in get_field
    return self.fields_map[field_name]
           ~~~~~~~~~~~~~~~^^^^^^^^^^^^
KeyError: 'bonus'

During handling of the above exception, another exception occurred:

Traceback (most recent call last):
  File "/Users/elgiz/flyexpert/backend/.venv/lib/python3.13/site-packages/django/contrib/admin/utils.py", line 290, in lookup_field
    f = _get_non_gfk_field(opts, name)
  File "/Users/elgiz/flyexpert/backend/.venv/lib/python3.13/site-packages/django/contrib/admin/utils.py", line 330, in _get_non_gfk_field
    field = opts.get_field(name)
  File "/Users/elgiz/flyexpert/backend/.venv/lib/python3.13/site-packages/django/db/models/options.py", line 678, in get_field
    raise FieldDoesNotExist(
        "%s has no field named '%s'" % (self.object_name, field_name)
    )
django.core.exceptions.FieldDoesNotExist: CustomUser has no field named 'bonus'

During handling of the above exception, another exception occurred:

Traceback (most recent call last):
  File "/Users/elgiz/flyexpert/backend/.venv/lib/python3.13/site-packages/django/db/models/fields/related_descriptors.py", line 512, in __get__
    rel_obj = self.related.get_cached_value(instance)
  File "/Users/elgiz/flyexpert/backend/.venv/lib/python3.13/site-packages/django/db/models/fields/mixins.py", line 37, in get_cached_value
    return instance._state.fields_cache[self.cache_name]
           ~~~~~~~~~~~~~~~~~~~~~~~~~~~~^^^^^^^^^^^^^^^^^
KeyError: 'userprofile'

During handling of the above exception, another exception occurred:

Traceback (most recent call last):
  File "/Users/elgiz/flyexpert/backend/.venv/lib/python3.13/site-packages/django/db/backends/utils.py", line 105, in _execute
    return self.cursor.execute(sql, params)
           ~~~~~~~~~~~~~~~~~~~^^^^^^^^^^^^^
  File "/Users/elgiz/flyexpert/backend/.venv/lib/python3.13/site-packages/django/db/backends/sqlite3/base.py", line 354, in execute
    return super().execute(query, params)
           ~~~~~~~~~~~~~~~^^^^^^^^^^^^^^^
sqlite3.OperationalError: no such table: accounts_userprofile

The above exception was the direct cause of the following exception:

Traceback (most recent call last):
  File "/Users/elgiz/flyexpert/backend/.venv/lib/python3.13/site-packages/django/core/handlers/exception.py", line 55, in inner
    response = get_response(request)
  File "/Users/elgiz/flyexpert/backend/.venv/lib/python3.13/site-packages/django/core/handlers/base.py", line 220, in _get_response
    response = response.render()
  File "/Users/elgiz/flyexpert/backend/.venv/lib/python3.13/site-packages/django/template/response.py", line 114, in render
    self.content = self.rendered_content
                   ^^^^^^^^^^^^^^^^^^^^^
  File "/Users/elgiz/flyexpert/backend/.venv/lib/python3.13/site-packages/django/template/response.py", line 92, in rendered_content
    return template.render(context, self._request)
           ~~~~~~~~~~~~~~~^^^^^^^^^^^^^^^^^^^^^^^^
  File "/Users/elgiz/flyexpert/backend/.venv/lib/python3.13/site-packages/django/template/backends/django.py", line 107, in render
    return self.template.render(context)
           ~~~~~~~~~~~~~~~~~~~~^^^^^^^^^
  File "/Users/elgiz/flyexpert/backend/.venv/lib/python3.13/site-packages/django/template/base.py", line 171, in render
    return self._render(context)
           ~~~~~~~~~~~~^^^^^^^^^
  File "/Users/elgiz/flyexpert/backend/.venv/lib/python3.13/site-packages/django/template/base.py", line 163, in _render
    return self.nodelist.render(context)
           ~~~~~~~~~~~~~~~~~~~~^^^^^^^^^
  File "/Users/elgiz/flyexpert/backend/.venv/lib/python3.13/site-packages/django/template/base.py", line 1008, in render
    return SafeString("".join([node.render_annotated(context) for node in self]))
                               ~~~~~~~~~~~~~~~~~~~~~^^^^^^^^^
  File "/Users/elgiz/flyexpert/backend/.venv/lib/python3.13/site-packages/django/template/base.py", line 969, in render_annotated
    return self.render(context)
           ~~~~~~~~~~~^^^^^^^^^
  File "/Users/elgiz/flyexpert/backend/.venv/lib/python3.13/site-packages/django/template/loader_tags.py", line 159, in render
    return compiled_parent._render(context)
           ~~~~~~~~~~~~~~~~~~~~~~~^^^^^^^^^
  File "/Users/elgiz/flyexpert/backend/.venv/lib/python3.13/site-packages/django/template/base.py", line 163, in _render
    return self.nodelist.render(context)
           ~~~~~~~~~~~~~~~~~~~~^^^^^^^^^
  File "/Users/elgiz/flyexpert/backend/.venv/lib/python3.13/site-packages/django/template/base.py", line 1008, in render
    return SafeString("".join([node.render_annotated(context) for node in self]))
                               ~~~~~~~~~~~~~~~~~~~~~^^^^^^^^^
  File "/Users/elgiz/flyexpert/backend/.venv/lib/python3.13/site-packages/django/template/base.py", line 969, in render_annotated
    return self.render(context)
           ~~~~~~~~~~~^^^^^^^^^
  File "/Users/elgiz/flyexpert/backend/.venv/lib/python3.13/site-packages/django/template/loader_tags.py", line 159, in render
    return compiled_parent._render(context)
           ~~~~~~~~~~~~~~~~~~~~~~~^^^^^^^^^
  File "/Users/elgiz/flyexpert/backend/.venv/lib/python3.13/site-packages/django/template/base.py", line 163, in _render
    return self.nodelist.render(context)
           ~~~~~~~~~~~~~~~~~~~~^^^^^^^^^
  File "/Users/elgiz/flyexpert/backend/.venv/lib/python3.13/site-packages/django/template/base.py", line 1008, in render
    return SafeString("".join([node.render_annotated(context) for node in self]))
                               ~~~~~~~~~~~~~~~~~~~~~^^^^^^^^^
  File "/Users/elgiz/flyexpert/backend/.venv/lib/python3.13/site-packages/django/template/base.py", line 969, in render_annotated
    return self.render(context)
           ~~~~~~~~~~~^^^^^^^^^
  File "/Users/elgiz/flyexpert/backend/.venv/lib/python3.13/site-packages/django/template/loader_tags.py", line 65, in render
    result = block.nodelist.render(context)
  File "/Users/elgiz/flyexpert/backend/.venv/lib/python3.13/site-packages/django/template/base.py", line 1008, in render
    return SafeString("".join([node.render_annotated(context) for node in self]))
                               ~~~~~~~~~~~~~~~~~~~~~^^^^^^^^^
  File "/Users/elgiz/flyexpert/backend/.venv/lib/python3.13/site-packages/django/template/base.py", line 969, in render_annotated
    return self.render(context)
           ~~~~~~~~~~~^^^^^^^^^
  File "/Users/elgiz/flyexpert/backend/.venv/lib/python3.13/site-packages/django/template/loader_tags.py", line 65, in render
    result = block.nodelist.render(context)
  File "/Users/elgiz/flyexpert/backend/.venv/lib/python3.13/site-packages/django/template/base.py", line 1008, in render
    return SafeString("".join([node.render_annotated(context) for node in self]))
                               ~~~~~~~~~~~~~~~~~~~~~^^^^^^^^^
  File "/Users/elgiz/flyexpert/backend/.venv/lib/python3.13/site-packages/django/template/base.py", line 969, in render_annotated
    return self.render(context)
           ~~~~~~~~~~~^^^^^^^^^
  File "/Users/elgiz/flyexpert/backend/.venv/lib/python3.13/site-packages/django/contrib/admin/templatetags/base.py", line 45, in render
    return super().render(context)
           ~~~~~~~~~~~~~~^^^^^^^^^
  File "/Users/elgiz/flyexpert/backend/.venv/lib/python3.13/site-packages/django/template/library.py", line 258, in render
    _dict = self.func(*resolved_args, **resolved_kwargs)
  File "/Users/elgiz/flyexpert/backend/.venv/lib/python3.13/site-packages/django/contrib/admin/templatetags/admin_list.py", line 346, in result_list
    "results": list(results(cl)),
               ~~~~^^^^^^^^^^^^^
  File "/Users/elgiz/flyexpert/backend/.venv/lib/python3.13/site-packages/django/contrib/admin/templatetags/admin_list.py", line 322, in results
    yield ResultList(None, items_for_result(cl, res, None))
          ~~~~~~~~~~^^^^^^^^^^^^^^^^^^^^^^^^^^^^^^^^^^^^^^^
  File "/Users/elgiz/flyexpert/backend/.venv/lib/python3.13/site-packages/django/contrib/admin/templatetags/admin_list.py", line 313, in __init__
    super().__init__(*items)
    ~~~~~~~~~~~~~~~~^^^^^^^^
  File "/Users/elgiz/flyexpert/backend/.venv/lib/python3.13/site-packages/django/contrib/admin/templatetags/admin_list.py", line 218, in items_for_result
    f, attr, value = lookup_field(field_name, result, cl.model_admin)
                     ~~~~~~~~~~~~^^^^^^^^^^^^^^^^^^^^^^^^^^^^^^^^^^^^
  File "/Users/elgiz/flyexpert/backend/.venv/lib/python3.13/site-packages/django/contrib/admin/utils.py", line 299, in lookup_field
    value = attr(obj)
  File "/Users/elgiz/flyexpert/backend/backend/accounts/admin.py", line 19, in bonus
    return obj.userprofile.bonus  # `UserProfile` modelindən bonus məlumatını qaytarır
           ^^^^^^^^^^^^^^^
  File "/Users/elgiz/flyexpert/backend/.venv/lib/python3.13/site-packages/django/db/models/fields/related_descriptors.py", line 520, in __get__
    rel_obj = self.get_queryset(instance=instance).get(**filter_args)
  File "/Users/elgiz/flyexpert/backend/.venv/lib/python3.13/site-packages/django/db/models/query.py", line 645, in get
    num = len(clone)
  File "/Users/elgiz/flyexpert/backend/.venv/lib/python3.13/site-packages/django/db/models/query.py", line 382, in __len__
    self._fetch_all()
    ~~~~~~~~~~~~~~~^^
  File "/Users/elgiz/flyexpert/backend/.venv/lib/python3.13/site-packages/django/db/models/query.py", line 1928, in _fetch_all
    self._result_cache = list(self._iterable_class(self))
                         ~~~~^^^^^^^^^^^^^^^^^^^^^^^^^^^^
  File "/Users/elgiz/flyexpert/backend/.venv/lib/python3.13/site-packages/django/db/models/query.py", line 91, in __iter__
    results = compiler.execute_sql(
        chunked_fetch=self.chunked_fetch, chunk_size=self.chunk_size
    )
  File "/Users/elgiz/flyexpert/backend/.venv/lib/python3.13/site-packages/django/db/models/sql/compiler.py", line 1574, in execute_sql
    cursor.execute(sql, params)
    ~~~~~~~~~~~~~~^^^^^^^^^^^^^
  File "/Users/elgiz/flyexpert/backend/.venv/lib/python3.13/site-packages/django/db/backends/utils.py", line 122, in execute
    return super().execute(sql, params)
           ~~~~~~~~~~~~~~~^^^^^^^^^^^^^
  File "/Users/elgiz/flyexpert/backend/.venv/lib/python3.13/site-packages/django/db/backends/utils.py", line 79, in execute
    return self._execute_with_wrappers(
           ~~~~~~~~~~~~~~~~~~~~~~~~~~~^
        sql, params, many=False, executor=self._execute
        ^^^^^^^^^^^^^^^^^^^^^^^^^^^^^^^^^^^^^^^^^^^^^^^
    )
    ^
  File "/Users/elgiz/flyexpert/backend/.venv/lib/python3.13/site-packages/django/db/backends/utils.py", line 92, in _execute_with_wrappers
    return executor(sql, params, many, context)
  File "/Users/elgiz/flyexpert/backend/.venv/lib/python3.13/site-packages/django/db/backends/utils.py", line 100, in _execute
    with self.db.wrap_database_errors:
         ^^^^^^^^^^^^^^^^^^^^^^^^^^^^
  File "/Users/elgiz/flyexpert/backend/.venv/lib/python3.13/site-packages/django/db/utils.py", line 91, in __exit__
    raise dj_exc_value.with_traceback(traceback) from exc_value
  File "/Users/elgiz/flyexpert/backend/.venv/lib/python3.13/site-packages/django/db/backends/utils.py", line 105, in _execute
    return self.cursor.execute(sql, params)
           ~~~~~~~~~~~~~~~~~~~^^^^^^^^^^^^^
  File "/Users/elgiz/flyexpert/backend/.venv/lib/python3.13/site-packages/django/db/backends/sqlite3/base.py", line 354, in execute
    return super().execute(query, params)
           ~~~~~~~~~~~~~~~^^^^^^^^^^^^^^^
django.db.utils.OperationalError: no such table: accounts_userprofile
ERROR 2025-03-01 17:41:08,622 basehttp "GET /admin/accounts/customuser/ HTTP/1.1" 500 453967
ERROR 2025-03-01 17:41:24,882 log Internal Server Error: /admin/accounts/customuser/
Traceback (most recent call last):
  File "/Users/elgiz/flyexpert/backend/.venv/lib/python3.13/site-packages/django/db/models/options.py", line 676, in get_field
    return self.fields_map[field_name]
           ~~~~~~~~~~~~~~~^^^^^^^^^^^^
KeyError: 'bonus'

During handling of the above exception, another exception occurred:

Traceback (most recent call last):
  File "/Users/elgiz/flyexpert/backend/.venv/lib/python3.13/site-packages/django/contrib/admin/utils.py", line 290, in lookup_field
    f = _get_non_gfk_field(opts, name)
  File "/Users/elgiz/flyexpert/backend/.venv/lib/python3.13/site-packages/django/contrib/admin/utils.py", line 330, in _get_non_gfk_field
    field = opts.get_field(name)
  File "/Users/elgiz/flyexpert/backend/.venv/lib/python3.13/site-packages/django/db/models/options.py", line 678, in get_field
    raise FieldDoesNotExist(
        "%s has no field named '%s'" % (self.object_name, field_name)
    )
django.core.exceptions.FieldDoesNotExist: CustomUser has no field named 'bonus'

During handling of the above exception, another exception occurred:

Traceback (most recent call last):
  File "/Users/elgiz/flyexpert/backend/.venv/lib/python3.13/site-packages/django/db/models/fields/related_descriptors.py", line 512, in __get__
    rel_obj = self.related.get_cached_value(instance)
  File "/Users/elgiz/flyexpert/backend/.venv/lib/python3.13/site-packages/django/db/models/fields/mixins.py", line 37, in get_cached_value
    return instance._state.fields_cache[self.cache_name]
           ~~~~~~~~~~~~~~~~~~~~~~~~~~~~^^^^^^^^^^^^^^^^^
KeyError: 'userprofile'

During handling of the above exception, another exception occurred:

Traceback (most recent call last):
  File "/Users/elgiz/flyexpert/backend/.venv/lib/python3.13/site-packages/django/db/backends/utils.py", line 105, in _execute
    return self.cursor.execute(sql, params)
           ~~~~~~~~~~~~~~~~~~~^^^^^^^^^^^^^
  File "/Users/elgiz/flyexpert/backend/.venv/lib/python3.13/site-packages/django/db/backends/sqlite3/base.py", line 354, in execute
    return super().execute(query, params)
           ~~~~~~~~~~~~~~~^^^^^^^^^^^^^^^
sqlite3.OperationalError: no such table: accounts_userprofile

The above exception was the direct cause of the following exception:

Traceback (most recent call last):
  File "/Users/elgiz/flyexpert/backend/.venv/lib/python3.13/site-packages/django/core/handlers/exception.py", line 55, in inner
    response = get_response(request)
  File "/Users/elgiz/flyexpert/backend/.venv/lib/python3.13/site-packages/django/core/handlers/base.py", line 220, in _get_response
    response = response.render()
  File "/Users/elgiz/flyexpert/backend/.venv/lib/python3.13/site-packages/django/template/response.py", line 114, in render
    self.content = self.rendered_content
                   ^^^^^^^^^^^^^^^^^^^^^
  File "/Users/elgiz/flyexpert/backend/.venv/lib/python3.13/site-packages/django/template/response.py", line 92, in rendered_content
    return template.render(context, self._request)
           ~~~~~~~~~~~~~~~^^^^^^^^^^^^^^^^^^^^^^^^
  File "/Users/elgiz/flyexpert/backend/.venv/lib/python3.13/site-packages/django/template/backends/django.py", line 107, in render
    return self.template.render(context)
           ~~~~~~~~~~~~~~~~~~~~^^^^^^^^^
  File "/Users/elgiz/flyexpert/backend/.venv/lib/python3.13/site-packages/django/template/base.py", line 171, in render
    return self._render(context)
           ~~~~~~~~~~~~^^^^^^^^^
  File "/Users/elgiz/flyexpert/backend/.venv/lib/python3.13/site-packages/django/template/base.py", line 163, in _render
    return self.nodelist.render(context)
           ~~~~~~~~~~~~~~~~~~~~^^^^^^^^^
  File "/Users/elgiz/flyexpert/backend/.venv/lib/python3.13/site-packages/django/template/base.py", line 1008, in render
    return SafeString("".join([node.render_annotated(context) for node in self]))
                               ~~~~~~~~~~~~~~~~~~~~~^^^^^^^^^
  File "/Users/elgiz/flyexpert/backend/.venv/lib/python3.13/site-packages/django/template/base.py", line 969, in render_annotated
    return self.render(context)
           ~~~~~~~~~~~^^^^^^^^^
  File "/Users/elgiz/flyexpert/backend/.venv/lib/python3.13/site-packages/django/template/loader_tags.py", line 159, in render
    return compiled_parent._render(context)
           ~~~~~~~~~~~~~~~~~~~~~~~^^^^^^^^^
  File "/Users/elgiz/flyexpert/backend/.venv/lib/python3.13/site-packages/django/template/base.py", line 163, in _render
    return self.nodelist.render(context)
           ~~~~~~~~~~~~~~~~~~~~^^^^^^^^^
  File "/Users/elgiz/flyexpert/backend/.venv/lib/python3.13/site-packages/django/template/base.py", line 1008, in render
    return SafeString("".join([node.render_annotated(context) for node in self]))
                               ~~~~~~~~~~~~~~~~~~~~~^^^^^^^^^
  File "/Users/elgiz/flyexpert/backend/.venv/lib/python3.13/site-packages/django/template/base.py", line 969, in render_annotated
    return self.render(context)
           ~~~~~~~~~~~^^^^^^^^^
  File "/Users/elgiz/flyexpert/backend/.venv/lib/python3.13/site-packages/django/template/loader_tags.py", line 159, in render
    return compiled_parent._render(context)
           ~~~~~~~~~~~~~~~~~~~~~~~^^^^^^^^^
  File "/Users/elgiz/flyexpert/backend/.venv/lib/python3.13/site-packages/django/template/base.py", line 163, in _render
    return self.nodelist.render(context)
           ~~~~~~~~~~~~~~~~~~~~^^^^^^^^^
  File "/Users/elgiz/flyexpert/backend/.venv/lib/python3.13/site-packages/django/template/base.py", line 1008, in render
    return SafeString("".join([node.render_annotated(context) for node in self]))
                               ~~~~~~~~~~~~~~~~~~~~~^^^^^^^^^
  File "/Users/elgiz/flyexpert/backend/.venv/lib/python3.13/site-packages/django/template/base.py", line 969, in render_annotated
    return self.render(context)
           ~~~~~~~~~~~^^^^^^^^^
  File "/Users/elgiz/flyexpert/backend/.venv/lib/python3.13/site-packages/django/template/loader_tags.py", line 65, in render
    result = block.nodelist.render(context)
  File "/Users/elgiz/flyexpert/backend/.venv/lib/python3.13/site-packages/django/template/base.py", line 1008, in render
    return SafeString("".join([node.render_annotated(context) for node in self]))
                               ~~~~~~~~~~~~~~~~~~~~~^^^^^^^^^
  File "/Users/elgiz/flyexpert/backend/.venv/lib/python3.13/site-packages/django/template/base.py", line 969, in render_annotated
    return self.render(context)
           ~~~~~~~~~~~^^^^^^^^^
  File "/Users/elgiz/flyexpert/backend/.venv/lib/python3.13/site-packages/django/template/loader_tags.py", line 65, in render
    result = block.nodelist.render(context)
  File "/Users/elgiz/flyexpert/backend/.venv/lib/python3.13/site-packages/django/template/base.py", line 1008, in render
    return SafeString("".join([node.render_annotated(context) for node in self]))
                               ~~~~~~~~~~~~~~~~~~~~~^^^^^^^^^
  File "/Users/elgiz/flyexpert/backend/.venv/lib/python3.13/site-packages/django/template/base.py", line 969, in render_annotated
    return self.render(context)
           ~~~~~~~~~~~^^^^^^^^^
  File "/Users/elgiz/flyexpert/backend/.venv/lib/python3.13/site-packages/django/contrib/admin/templatetags/base.py", line 45, in render
    return super().render(context)
           ~~~~~~~~~~~~~~^^^^^^^^^
  File "/Users/elgiz/flyexpert/backend/.venv/lib/python3.13/site-packages/django/template/library.py", line 258, in render
    _dict = self.func(*resolved_args, **resolved_kwargs)
  File "/Users/elgiz/flyexpert/backend/.venv/lib/python3.13/site-packages/django/contrib/admin/templatetags/admin_list.py", line 346, in result_list
    "results": list(results(cl)),
               ~~~~^^^^^^^^^^^^^
  File "/Users/elgiz/flyexpert/backend/.venv/lib/python3.13/site-packages/django/contrib/admin/templatetags/admin_list.py", line 322, in results
    yield ResultList(None, items_for_result(cl, res, None))
          ~~~~~~~~~~^^^^^^^^^^^^^^^^^^^^^^^^^^^^^^^^^^^^^^^
  File "/Users/elgiz/flyexpert/backend/.venv/lib/python3.13/site-packages/django/contrib/admin/templatetags/admin_list.py", line 313, in __init__
    super().__init__(*items)
    ~~~~~~~~~~~~~~~~^^^^^^^^
  File "/Users/elgiz/flyexpert/backend/.venv/lib/python3.13/site-packages/django/contrib/admin/templatetags/admin_list.py", line 218, in items_for_result
    f, attr, value = lookup_field(field_name, result, cl.model_admin)
                     ~~~~~~~~~~~~^^^^^^^^^^^^^^^^^^^^^^^^^^^^^^^^^^^^
  File "/Users/elgiz/flyexpert/backend/.venv/lib/python3.13/site-packages/django/contrib/admin/utils.py", line 299, in lookup_field
    value = attr(obj)
  File "/Users/elgiz/flyexpert/backend/backend/accounts/admin.py", line 19, in bonus
    return obj.userprofile.bonus  # `UserProfile` modelindən bonus məlumatını qaytarır
           ^^^^^^^^^^^^^^^
  File "/Users/elgiz/flyexpert/backend/.venv/lib/python3.13/site-packages/django/db/models/fields/related_descriptors.py", line 520, in __get__
    rel_obj = self.get_queryset(instance=instance).get(**filter_args)
  File "/Users/elgiz/flyexpert/backend/.venv/lib/python3.13/site-packages/django/db/models/query.py", line 645, in get
    num = len(clone)
  File "/Users/elgiz/flyexpert/backend/.venv/lib/python3.13/site-packages/django/db/models/query.py", line 382, in __len__
    self._fetch_all()
    ~~~~~~~~~~~~~~~^^
  File "/Users/elgiz/flyexpert/backend/.venv/lib/python3.13/site-packages/django/db/models/query.py", line 1928, in _fetch_all
    self._result_cache = list(self._iterable_class(self))
                         ~~~~^^^^^^^^^^^^^^^^^^^^^^^^^^^^
  File "/Users/elgiz/flyexpert/backend/.venv/lib/python3.13/site-packages/django/db/models/query.py", line 91, in __iter__
    results = compiler.execute_sql(
        chunked_fetch=self.chunked_fetch, chunk_size=self.chunk_size
    )
  File "/Users/elgiz/flyexpert/backend/.venv/lib/python3.13/site-packages/django/db/models/sql/compiler.py", line 1574, in execute_sql
    cursor.execute(sql, params)
    ~~~~~~~~~~~~~~^^^^^^^^^^^^^
  File "/Users/elgiz/flyexpert/backend/.venv/lib/python3.13/site-packages/django/db/backends/utils.py", line 122, in execute
    return super().execute(sql, params)
           ~~~~~~~~~~~~~~~^^^^^^^^^^^^^
  File "/Users/elgiz/flyexpert/backend/.venv/lib/python3.13/site-packages/django/db/backends/utils.py", line 79, in execute
    return self._execute_with_wrappers(
           ~~~~~~~~~~~~~~~~~~~~~~~~~~~^
        sql, params, many=False, executor=self._execute
        ^^^^^^^^^^^^^^^^^^^^^^^^^^^^^^^^^^^^^^^^^^^^^^^
    )
    ^
  File "/Users/elgiz/flyexpert/backend/.venv/lib/python3.13/site-packages/django/db/backends/utils.py", line 92, in _execute_with_wrappers
    return executor(sql, params, many, context)
  File "/Users/elgiz/flyexpert/backend/.venv/lib/python3.13/site-packages/django/db/backends/utils.py", line 100, in _execute
    with self.db.wrap_database_errors:
         ^^^^^^^^^^^^^^^^^^^^^^^^^^^^
  File "/Users/elgiz/flyexpert/backend/.venv/lib/python3.13/site-packages/django/db/utils.py", line 91, in __exit__
    raise dj_exc_value.with_traceback(traceback) from exc_value
  File "/Users/elgiz/flyexpert/backend/.venv/lib/python3.13/site-packages/django/db/backends/utils.py", line 105, in _execute
    return self.cursor.execute(sql, params)
           ~~~~~~~~~~~~~~~~~~~^^^^^^^^^^^^^
  File "/Users/elgiz/flyexpert/backend/.venv/lib/python3.13/site-packages/django/db/backends/sqlite3/base.py", line 354, in execute
    return super().execute(query, params)
           ~~~~~~~~~~~~~~~^^^^^^^^^^^^^^^
django.db.utils.OperationalError: no such table: accounts_userprofile
ERROR 2025-03-01 17:41:24,909 basehttp "GET /admin/accounts/customuser/ HTTP/1.1" 500 453958
ERROR 2025-03-01 18:20:03,948 log Internal Server Error: /admin/accounts/customuser/
Traceback (most recent call last):
  File "/Users/elgiz/flyexpert/backend/.venv/lib/python3.13/site-packages/django/db/models/options.py", line 676, in get_field
    return self.fields_map[field_name]
           ~~~~~~~~~~~~~~~^^^^^^^^^^^^
KeyError: 'bonus'

During handling of the above exception, another exception occurred:

Traceback (most recent call last):
  File "/Users/elgiz/flyexpert/backend/.venv/lib/python3.13/site-packages/django/contrib/admin/utils.py", line 290, in lookup_field
    f = _get_non_gfk_field(opts, name)
  File "/Users/elgiz/flyexpert/backend/.venv/lib/python3.13/site-packages/django/contrib/admin/utils.py", line 330, in _get_non_gfk_field
    field = opts.get_field(name)
  File "/Users/elgiz/flyexpert/backend/.venv/lib/python3.13/site-packages/django/db/models/options.py", line 678, in get_field
    raise FieldDoesNotExist(
        "%s has no field named '%s'" % (self.object_name, field_name)
    )
django.core.exceptions.FieldDoesNotExist: CustomUser has no field named 'bonus'

During handling of the above exception, another exception occurred:

Traceback (most recent call last):
  File "/Users/elgiz/flyexpert/backend/.venv/lib/python3.13/site-packages/django/db/models/fields/related_descriptors.py", line 512, in __get__
    rel_obj = self.related.get_cached_value(instance)
  File "/Users/elgiz/flyexpert/backend/.venv/lib/python3.13/site-packages/django/db/models/fields/mixins.py", line 37, in get_cached_value
    return instance._state.fields_cache[self.cache_name]
           ~~~~~~~~~~~~~~~~~~~~~~~~~~~~^^^^^^^^^^^^^^^^^
KeyError: 'userprofile'

During handling of the above exception, another exception occurred:

Traceback (most recent call last):
  File "/Users/elgiz/flyexpert/backend/.venv/lib/python3.13/site-packages/django/db/backends/utils.py", line 105, in _execute
    return self.cursor.execute(sql, params)
           ~~~~~~~~~~~~~~~~~~~^^^^^^^^^^^^^
  File "/Users/elgiz/flyexpert/backend/.venv/lib/python3.13/site-packages/django/db/backends/sqlite3/base.py", line 354, in execute
    return super().execute(query, params)
           ~~~~~~~~~~~~~~~^^^^^^^^^^^^^^^
sqlite3.OperationalError: no such table: accounts_userprofile

The above exception was the direct cause of the following exception:

Traceback (most recent call last):
  File "/Users/elgiz/flyexpert/backend/.venv/lib/python3.13/site-packages/django/core/handlers/exception.py", line 55, in inner
    response = get_response(request)
  File "/Users/elgiz/flyexpert/backend/.venv/lib/python3.13/site-packages/django/core/handlers/base.py", line 220, in _get_response
    response = response.render()
  File "/Users/elgiz/flyexpert/backend/.venv/lib/python3.13/site-packages/django/template/response.py", line 114, in render
    self.content = self.rendered_content
                   ^^^^^^^^^^^^^^^^^^^^^
  File "/Users/elgiz/flyexpert/backend/.venv/lib/python3.13/site-packages/django/template/response.py", line 92, in rendered_content
    return template.render(context, self._request)
           ~~~~~~~~~~~~~~~^^^^^^^^^^^^^^^^^^^^^^^^
  File "/Users/elgiz/flyexpert/backend/.venv/lib/python3.13/site-packages/django/template/backends/django.py", line 107, in render
    return self.template.render(context)
           ~~~~~~~~~~~~~~~~~~~~^^^^^^^^^
  File "/Users/elgiz/flyexpert/backend/.venv/lib/python3.13/site-packages/django/template/base.py", line 171, in render
    return self._render(context)
           ~~~~~~~~~~~~^^^^^^^^^
  File "/Users/elgiz/flyexpert/backend/.venv/lib/python3.13/site-packages/django/template/base.py", line 163, in _render
    return self.nodelist.render(context)
           ~~~~~~~~~~~~~~~~~~~~^^^^^^^^^
  File "/Users/elgiz/flyexpert/backend/.venv/lib/python3.13/site-packages/django/template/base.py", line 1008, in render
    return SafeString("".join([node.render_annotated(context) for node in self]))
                               ~~~~~~~~~~~~~~~~~~~~~^^^^^^^^^
  File "/Users/elgiz/flyexpert/backend/.venv/lib/python3.13/site-packages/django/template/base.py", line 969, in render_annotated
    return self.render(context)
           ~~~~~~~~~~~^^^^^^^^^
  File "/Users/elgiz/flyexpert/backend/.venv/lib/python3.13/site-packages/django/template/loader_tags.py", line 159, in render
    return compiled_parent._render(context)
           ~~~~~~~~~~~~~~~~~~~~~~~^^^^^^^^^
  File "/Users/elgiz/flyexpert/backend/.venv/lib/python3.13/site-packages/django/template/base.py", line 163, in _render
    return self.nodelist.render(context)
           ~~~~~~~~~~~~~~~~~~~~^^^^^^^^^
  File "/Users/elgiz/flyexpert/backend/.venv/lib/python3.13/site-packages/django/template/base.py", line 1008, in render
    return SafeString("".join([node.render_annotated(context) for node in self]))
                               ~~~~~~~~~~~~~~~~~~~~~^^^^^^^^^
  File "/Users/elgiz/flyexpert/backend/.venv/lib/python3.13/site-packages/django/template/base.py", line 969, in render_annotated
    return self.render(context)
           ~~~~~~~~~~~^^^^^^^^^
  File "/Users/elgiz/flyexpert/backend/.venv/lib/python3.13/site-packages/django/template/loader_tags.py", line 159, in render
    return compiled_parent._render(context)
           ~~~~~~~~~~~~~~~~~~~~~~~^^^^^^^^^
  File "/Users/elgiz/flyexpert/backend/.venv/lib/python3.13/site-packages/django/template/base.py", line 163, in _render
    return self.nodelist.render(context)
           ~~~~~~~~~~~~~~~~~~~~^^^^^^^^^
  File "/Users/elgiz/flyexpert/backend/.venv/lib/python3.13/site-packages/django/template/base.py", line 1008, in render
    return SafeString("".join([node.render_annotated(context) for node in self]))
                               ~~~~~~~~~~~~~~~~~~~~~^^^^^^^^^
  File "/Users/elgiz/flyexpert/backend/.venv/lib/python3.13/site-packages/django/template/base.py", line 969, in render_annotated
    return self.render(context)
           ~~~~~~~~~~~^^^^^^^^^
  File "/Users/elgiz/flyexpert/backend/.venv/lib/python3.13/site-packages/django/template/loader_tags.py", line 65, in render
    result = block.nodelist.render(context)
  File "/Users/elgiz/flyexpert/backend/.venv/lib/python3.13/site-packages/django/template/base.py", line 1008, in render
    return SafeString("".join([node.render_annotated(context) for node in self]))
                               ~~~~~~~~~~~~~~~~~~~~~^^^^^^^^^
  File "/Users/elgiz/flyexpert/backend/.venv/lib/python3.13/site-packages/django/template/base.py", line 969, in render_annotated
    return self.render(context)
           ~~~~~~~~~~~^^^^^^^^^
  File "/Users/elgiz/flyexpert/backend/.venv/lib/python3.13/site-packages/django/template/loader_tags.py", line 65, in render
    result = block.nodelist.render(context)
  File "/Users/elgiz/flyexpert/backend/.venv/lib/python3.13/site-packages/django/template/base.py", line 1008, in render
    return SafeString("".join([node.render_annotated(context) for node in self]))
                               ~~~~~~~~~~~~~~~~~~~~~^^^^^^^^^
  File "/Users/elgiz/flyexpert/backend/.venv/lib/python3.13/site-packages/django/template/base.py", line 969, in render_annotated
    return self.render(context)
           ~~~~~~~~~~~^^^^^^^^^
  File "/Users/elgiz/flyexpert/backend/.venv/lib/python3.13/site-packages/django/contrib/admin/templatetags/base.py", line 45, in render
    return super().render(context)
           ~~~~~~~~~~~~~~^^^^^^^^^
  File "/Users/elgiz/flyexpert/backend/.venv/lib/python3.13/site-packages/django/template/library.py", line 258, in render
    _dict = self.func(*resolved_args, **resolved_kwargs)
  File "/Users/elgiz/flyexpert/backend/.venv/lib/python3.13/site-packages/django/contrib/admin/templatetags/admin_list.py", line 346, in result_list
    "results": list(results(cl)),
               ~~~~^^^^^^^^^^^^^
  File "/Users/elgiz/flyexpert/backend/.venv/lib/python3.13/site-packages/django/contrib/admin/templatetags/admin_list.py", line 322, in results
    yield ResultList(None, items_for_result(cl, res, None))
          ~~~~~~~~~~^^^^^^^^^^^^^^^^^^^^^^^^^^^^^^^^^^^^^^^
  File "/Users/elgiz/flyexpert/backend/.venv/lib/python3.13/site-packages/django/contrib/admin/templatetags/admin_list.py", line 313, in __init__
    super().__init__(*items)
    ~~~~~~~~~~~~~~~~^^^^^^^^
  File "/Users/elgiz/flyexpert/backend/.venv/lib/python3.13/site-packages/django/contrib/admin/templatetags/admin_list.py", line 218, in items_for_result
    f, attr, value = lookup_field(field_name, result, cl.model_admin)
                     ~~~~~~~~~~~~^^^^^^^^^^^^^^^^^^^^^^^^^^^^^^^^^^^^
  File "/Users/elgiz/flyexpert/backend/.venv/lib/python3.13/site-packages/django/contrib/admin/utils.py", line 299, in lookup_field
    value = attr(obj)
  File "/Users/elgiz/flyexpert/backend/backend/accounts/admin.py", line 19, in bonus
    return obj.userprofile.bonus  # `UserProfile` modelindən bonus məlumatını qaytarır
           ^^^^^^^^^^^^^^^
  File "/Users/elgiz/flyexpert/backend/.venv/lib/python3.13/site-packages/django/db/models/fields/related_descriptors.py", line 520, in __get__
    rel_obj = self.get_queryset(instance=instance).get(**filter_args)
  File "/Users/elgiz/flyexpert/backend/.venv/lib/python3.13/site-packages/django/db/models/query.py", line 645, in get
    num = len(clone)
  File "/Users/elgiz/flyexpert/backend/.venv/lib/python3.13/site-packages/django/db/models/query.py", line 382, in __len__
    self._fetch_all()
    ~~~~~~~~~~~~~~~^^
  File "/Users/elgiz/flyexpert/backend/.venv/lib/python3.13/site-packages/django/db/models/query.py", line 1928, in _fetch_all
    self._result_cache = list(self._iterable_class(self))
                         ~~~~^^^^^^^^^^^^^^^^^^^^^^^^^^^^
  File "/Users/elgiz/flyexpert/backend/.venv/lib/python3.13/site-packages/django/db/models/query.py", line 91, in __iter__
    results = compiler.execute_sql(
        chunked_fetch=self.chunked_fetch, chunk_size=self.chunk_size
    )
  File "/Users/elgiz/flyexpert/backend/.venv/lib/python3.13/site-packages/django/db/models/sql/compiler.py", line 1574, in execute_sql
    cursor.execute(sql, params)
    ~~~~~~~~~~~~~~^^^^^^^^^^^^^
  File "/Users/elgiz/flyexpert/backend/.venv/lib/python3.13/site-packages/django/db/backends/utils.py", line 122, in execute
    return super().execute(sql, params)
           ~~~~~~~~~~~~~~~^^^^^^^^^^^^^
  File "/Users/elgiz/flyexpert/backend/.venv/lib/python3.13/site-packages/django/db/backends/utils.py", line 79, in execute
    return self._execute_with_wrappers(
           ~~~~~~~~~~~~~~~~~~~~~~~~~~~^
        sql, params, many=False, executor=self._execute
        ^^^^^^^^^^^^^^^^^^^^^^^^^^^^^^^^^^^^^^^^^^^^^^^
    )
    ^
  File "/Users/elgiz/flyexpert/backend/.venv/lib/python3.13/site-packages/django/db/backends/utils.py", line 92, in _execute_with_wrappers
    return executor(sql, params, many, context)
  File "/Users/elgiz/flyexpert/backend/.venv/lib/python3.13/site-packages/django/db/backends/utils.py", line 100, in _execute
    with self.db.wrap_database_errors:
         ^^^^^^^^^^^^^^^^^^^^^^^^^^^^
  File "/Users/elgiz/flyexpert/backend/.venv/lib/python3.13/site-packages/django/db/utils.py", line 91, in __exit__
    raise dj_exc_value.with_traceback(traceback) from exc_value
  File "/Users/elgiz/flyexpert/backend/.venv/lib/python3.13/site-packages/django/db/backends/utils.py", line 105, in _execute
    return self.cursor.execute(sql, params)
           ~~~~~~~~~~~~~~~~~~~^^^^^^^^^^^^^
  File "/Users/elgiz/flyexpert/backend/.venv/lib/python3.13/site-packages/django/db/backends/sqlite3/base.py", line 354, in execute
    return super().execute(query, params)
           ~~~~~~~~~~~~~~~^^^^^^^^^^^^^^^
django.db.utils.OperationalError: no such table: accounts_userprofile
ERROR 2025-03-01 18:20:03,969 basehttp "GET /admin/accounts/customuser/ HTTP/1.1" 500 453958
ERROR 2025-03-01 18:20:08,875 log Internal Server Error: /admin/accounts/customuser/
Traceback (most recent call last):
  File "/Users/elgiz/flyexpert/backend/.venv/lib/python3.13/site-packages/django/db/models/options.py", line 676, in get_field
    return self.fields_map[field_name]
           ~~~~~~~~~~~~~~~^^^^^^^^^^^^
KeyError: 'bonus'

During handling of the above exception, another exception occurred:

Traceback (most recent call last):
  File "/Users/elgiz/flyexpert/backend/.venv/lib/python3.13/site-packages/django/contrib/admin/utils.py", line 290, in lookup_field
    f = _get_non_gfk_field(opts, name)
  File "/Users/elgiz/flyexpert/backend/.venv/lib/python3.13/site-packages/django/contrib/admin/utils.py", line 330, in _get_non_gfk_field
    field = opts.get_field(name)
  File "/Users/elgiz/flyexpert/backend/.venv/lib/python3.13/site-packages/django/db/models/options.py", line 678, in get_field
    raise FieldDoesNotExist(
        "%s has no field named '%s'" % (self.object_name, field_name)
    )
django.core.exceptions.FieldDoesNotExist: CustomUser has no field named 'bonus'

During handling of the above exception, another exception occurred:

Traceback (most recent call last):
  File "/Users/elgiz/flyexpert/backend/.venv/lib/python3.13/site-packages/django/db/models/fields/related_descriptors.py", line 512, in __get__
    rel_obj = self.related.get_cached_value(instance)
  File "/Users/elgiz/flyexpert/backend/.venv/lib/python3.13/site-packages/django/db/models/fields/mixins.py", line 37, in get_cached_value
    return instance._state.fields_cache[self.cache_name]
           ~~~~~~~~~~~~~~~~~~~~~~~~~~~~^^^^^^^^^^^^^^^^^
KeyError: 'userprofile'

During handling of the above exception, another exception occurred:

Traceback (most recent call last):
  File "/Users/elgiz/flyexpert/backend/.venv/lib/python3.13/site-packages/django/db/backends/utils.py", line 105, in _execute
    return self.cursor.execute(sql, params)
           ~~~~~~~~~~~~~~~~~~~^^^^^^^^^^^^^
  File "/Users/elgiz/flyexpert/backend/.venv/lib/python3.13/site-packages/django/db/backends/sqlite3/base.py", line 354, in execute
    return super().execute(query, params)
           ~~~~~~~~~~~~~~~^^^^^^^^^^^^^^^
sqlite3.OperationalError: no such table: accounts_userprofile

The above exception was the direct cause of the following exception:

Traceback (most recent call last):
  File "/Users/elgiz/flyexpert/backend/.venv/lib/python3.13/site-packages/django/core/handlers/exception.py", line 55, in inner
    response = get_response(request)
  File "/Users/elgiz/flyexpert/backend/.venv/lib/python3.13/site-packages/django/core/handlers/base.py", line 220, in _get_response
    response = response.render()
  File "/Users/elgiz/flyexpert/backend/.venv/lib/python3.13/site-packages/django/template/response.py", line 114, in render
    self.content = self.rendered_content
                   ^^^^^^^^^^^^^^^^^^^^^
  File "/Users/elgiz/flyexpert/backend/.venv/lib/python3.13/site-packages/django/template/response.py", line 92, in rendered_content
    return template.render(context, self._request)
           ~~~~~~~~~~~~~~~^^^^^^^^^^^^^^^^^^^^^^^^
  File "/Users/elgiz/flyexpert/backend/.venv/lib/python3.13/site-packages/django/template/backends/django.py", line 107, in render
    return self.template.render(context)
           ~~~~~~~~~~~~~~~~~~~~^^^^^^^^^
  File "/Users/elgiz/flyexpert/backend/.venv/lib/python3.13/site-packages/django/template/base.py", line 171, in render
    return self._render(context)
           ~~~~~~~~~~~~^^^^^^^^^
  File "/Users/elgiz/flyexpert/backend/.venv/lib/python3.13/site-packages/django/template/base.py", line 163, in _render
    return self.nodelist.render(context)
           ~~~~~~~~~~~~~~~~~~~~^^^^^^^^^
  File "/Users/elgiz/flyexpert/backend/.venv/lib/python3.13/site-packages/django/template/base.py", line 1008, in render
    return SafeString("".join([node.render_annotated(context) for node in self]))
                               ~~~~~~~~~~~~~~~~~~~~~^^^^^^^^^
  File "/Users/elgiz/flyexpert/backend/.venv/lib/python3.13/site-packages/django/template/base.py", line 969, in render_annotated
    return self.render(context)
           ~~~~~~~~~~~^^^^^^^^^
  File "/Users/elgiz/flyexpert/backend/.venv/lib/python3.13/site-packages/django/template/loader_tags.py", line 159, in render
    return compiled_parent._render(context)
           ~~~~~~~~~~~~~~~~~~~~~~~^^^^^^^^^
  File "/Users/elgiz/flyexpert/backend/.venv/lib/python3.13/site-packages/django/template/base.py", line 163, in _render
    return self.nodelist.render(context)
           ~~~~~~~~~~~~~~~~~~~~^^^^^^^^^
  File "/Users/elgiz/flyexpert/backend/.venv/lib/python3.13/site-packages/django/template/base.py", line 1008, in render
    return SafeString("".join([node.render_annotated(context) for node in self]))
                               ~~~~~~~~~~~~~~~~~~~~~^^^^^^^^^
  File "/Users/elgiz/flyexpert/backend/.venv/lib/python3.13/site-packages/django/template/base.py", line 969, in render_annotated
    return self.render(context)
           ~~~~~~~~~~~^^^^^^^^^
  File "/Users/elgiz/flyexpert/backend/.venv/lib/python3.13/site-packages/django/template/loader_tags.py", line 159, in render
    return compiled_parent._render(context)
           ~~~~~~~~~~~~~~~~~~~~~~~^^^^^^^^^
  File "/Users/elgiz/flyexpert/backend/.venv/lib/python3.13/site-packages/django/template/base.py", line 163, in _render
    return self.nodelist.render(context)
           ~~~~~~~~~~~~~~~~~~~~^^^^^^^^^
  File "/Users/elgiz/flyexpert/backend/.venv/lib/python3.13/site-packages/django/template/base.py", line 1008, in render
    return SafeString("".join([node.render_annotated(context) for node in self]))
                               ~~~~~~~~~~~~~~~~~~~~~^^^^^^^^^
  File "/Users/elgiz/flyexpert/backend/.venv/lib/python3.13/site-packages/django/template/base.py", line 969, in render_annotated
    return self.render(context)
           ~~~~~~~~~~~^^^^^^^^^
  File "/Users/elgiz/flyexpert/backend/.venv/lib/python3.13/site-packages/django/template/loader_tags.py", line 65, in render
    result = block.nodelist.render(context)
  File "/Users/elgiz/flyexpert/backend/.venv/lib/python3.13/site-packages/django/template/base.py", line 1008, in render
    return SafeString("".join([node.render_annotated(context) for node in self]))
                               ~~~~~~~~~~~~~~~~~~~~~^^^^^^^^^
  File "/Users/elgiz/flyexpert/backend/.venv/lib/python3.13/site-packages/django/template/base.py", line 969, in render_annotated
    return self.render(context)
           ~~~~~~~~~~~^^^^^^^^^
  File "/Users/elgiz/flyexpert/backend/.venv/lib/python3.13/site-packages/django/template/loader_tags.py", line 65, in render
    result = block.nodelist.render(context)
  File "/Users/elgiz/flyexpert/backend/.venv/lib/python3.13/site-packages/django/template/base.py", line 1008, in render
    return SafeString("".join([node.render_annotated(context) for node in self]))
                               ~~~~~~~~~~~~~~~~~~~~~^^^^^^^^^
  File "/Users/elgiz/flyexpert/backend/.venv/lib/python3.13/site-packages/django/template/base.py", line 969, in render_annotated
    return self.render(context)
           ~~~~~~~~~~~^^^^^^^^^
  File "/Users/elgiz/flyexpert/backend/.venv/lib/python3.13/site-packages/django/contrib/admin/templatetags/base.py", line 45, in render
    return super().render(context)
           ~~~~~~~~~~~~~~^^^^^^^^^
  File "/Users/elgiz/flyexpert/backend/.venv/lib/python3.13/site-packages/django/template/library.py", line 258, in render
    _dict = self.func(*resolved_args, **resolved_kwargs)
  File "/Users/elgiz/flyexpert/backend/.venv/lib/python3.13/site-packages/django/contrib/admin/templatetags/admin_list.py", line 346, in result_list
    "results": list(results(cl)),
               ~~~~^^^^^^^^^^^^^
  File "/Users/elgiz/flyexpert/backend/.venv/lib/python3.13/site-packages/django/contrib/admin/templatetags/admin_list.py", line 322, in results
    yield ResultList(None, items_for_result(cl, res, None))
          ~~~~~~~~~~^^^^^^^^^^^^^^^^^^^^^^^^^^^^^^^^^^^^^^^
  File "/Users/elgiz/flyexpert/backend/.venv/lib/python3.13/site-packages/django/contrib/admin/templatetags/admin_list.py", line 313, in __init__
    super().__init__(*items)
    ~~~~~~~~~~~~~~~~^^^^^^^^
  File "/Users/elgiz/flyexpert/backend/.venv/lib/python3.13/site-packages/django/contrib/admin/templatetags/admin_list.py", line 218, in items_for_result
    f, attr, value = lookup_field(field_name, result, cl.model_admin)
                     ~~~~~~~~~~~~^^^^^^^^^^^^^^^^^^^^^^^^^^^^^^^^^^^^
  File "/Users/elgiz/flyexpert/backend/.venv/lib/python3.13/site-packages/django/contrib/admin/utils.py", line 299, in lookup_field
    value = attr(obj)
  File "/Users/elgiz/flyexpert/backend/backend/accounts/admin.py", line 19, in bonus
    return obj.userprofile.bonus  # `UserProfile` modelindən bonus məlumatını qaytarır
           ^^^^^^^^^^^^^^^
  File "/Users/elgiz/flyexpert/backend/.venv/lib/python3.13/site-packages/django/db/models/fields/related_descriptors.py", line 520, in __get__
    rel_obj = self.get_queryset(instance=instance).get(**filter_args)
  File "/Users/elgiz/flyexpert/backend/.venv/lib/python3.13/site-packages/django/db/models/query.py", line 645, in get
    num = len(clone)
  File "/Users/elgiz/flyexpert/backend/.venv/lib/python3.13/site-packages/django/db/models/query.py", line 382, in __len__
    self._fetch_all()
    ~~~~~~~~~~~~~~~^^
  File "/Users/elgiz/flyexpert/backend/.venv/lib/python3.13/site-packages/django/db/models/query.py", line 1928, in _fetch_all
    self._result_cache = list(self._iterable_class(self))
                         ~~~~^^^^^^^^^^^^^^^^^^^^^^^^^^^^
  File "/Users/elgiz/flyexpert/backend/.venv/lib/python3.13/site-packages/django/db/models/query.py", line 91, in __iter__
    results = compiler.execute_sql(
        chunked_fetch=self.chunked_fetch, chunk_size=self.chunk_size
    )
  File "/Users/elgiz/flyexpert/backend/.venv/lib/python3.13/site-packages/django/db/models/sql/compiler.py", line 1574, in execute_sql
    cursor.execute(sql, params)
    ~~~~~~~~~~~~~~^^^^^^^^^^^^^
  File "/Users/elgiz/flyexpert/backend/.venv/lib/python3.13/site-packages/django/db/backends/utils.py", line 122, in execute
    return super().execute(sql, params)
           ~~~~~~~~~~~~~~~^^^^^^^^^^^^^
  File "/Users/elgiz/flyexpert/backend/.venv/lib/python3.13/site-packages/django/db/backends/utils.py", line 79, in execute
    return self._execute_with_wrappers(
           ~~~~~~~~~~~~~~~~~~~~~~~~~~~^
        sql, params, many=False, executor=self._execute
        ^^^^^^^^^^^^^^^^^^^^^^^^^^^^^^^^^^^^^^^^^^^^^^^
    )
    ^
  File "/Users/elgiz/flyexpert/backend/.venv/lib/python3.13/site-packages/django/db/backends/utils.py", line 92, in _execute_with_wrappers
    return executor(sql, params, many, context)
  File "/Users/elgiz/flyexpert/backend/.venv/lib/python3.13/site-packages/django/db/backends/utils.py", line 100, in _execute
    with self.db.wrap_database_errors:
         ^^^^^^^^^^^^^^^^^^^^^^^^^^^^
  File "/Users/elgiz/flyexpert/backend/.venv/lib/python3.13/site-packages/django/db/utils.py", line 91, in __exit__
    raise dj_exc_value.with_traceback(traceback) from exc_value
  File "/Users/elgiz/flyexpert/backend/.venv/lib/python3.13/site-packages/django/db/backends/utils.py", line 105, in _execute
    return self.cursor.execute(sql, params)
           ~~~~~~~~~~~~~~~~~~~^^^^^^^^^^^^^
  File "/Users/elgiz/flyexpert/backend/.venv/lib/python3.13/site-packages/django/db/backends/sqlite3/base.py", line 354, in execute
    return super().execute(query, params)
           ~~~~~~~~~~~~~~~^^^^^^^^^^^^^^^
django.db.utils.OperationalError: no such table: accounts_userprofile
ERROR 2025-03-01 18:20:08,904 basehttp "GET /admin/accounts/customuser/ HTTP/1.1" 500 453958
ERROR 2025-03-02 03:27:07,418 log Internal Server Error: /admin/accounts/customuser/
Traceback (most recent call last):
  File "/Users/elgiz/flyexpert/backend/.venv/lib/python3.13/site-packages/django/db/models/options.py", line 676, in get_field
    return self.fields_map[field_name]
           ~~~~~~~~~~~~~~~^^^^^^^^^^^^
KeyError: 'bonus'

During handling of the above exception, another exception occurred:

Traceback (most recent call last):
  File "/Users/elgiz/flyexpert/backend/.venv/lib/python3.13/site-packages/django/contrib/admin/utils.py", line 290, in lookup_field
    f = _get_non_gfk_field(opts, name)
  File "/Users/elgiz/flyexpert/backend/.venv/lib/python3.13/site-packages/django/contrib/admin/utils.py", line 330, in _get_non_gfk_field
    field = opts.get_field(name)
  File "/Users/elgiz/flyexpert/backend/.venv/lib/python3.13/site-packages/django/db/models/options.py", line 678, in get_field
    raise FieldDoesNotExist(
        "%s has no field named '%s'" % (self.object_name, field_name)
    )
django.core.exceptions.FieldDoesNotExist: CustomUser has no field named 'bonus'

During handling of the above exception, another exception occurred:

Traceback (most recent call last):
  File "/Users/elgiz/flyexpert/backend/.venv/lib/python3.13/site-packages/django/db/models/fields/related_descriptors.py", line 512, in __get__
    rel_obj = self.related.get_cached_value(instance)
  File "/Users/elgiz/flyexpert/backend/.venv/lib/python3.13/site-packages/django/db/models/fields/mixins.py", line 37, in get_cached_value
    return instance._state.fields_cache[self.cache_name]
           ~~~~~~~~~~~~~~~~~~~~~~~~~~~~^^^^^^^^^^^^^^^^^
KeyError: 'userprofile'

During handling of the above exception, another exception occurred:

Traceback (most recent call last):
  File "/Users/elgiz/flyexpert/backend/.venv/lib/python3.13/site-packages/django/db/backends/utils.py", line 105, in _execute
    return self.cursor.execute(sql, params)
           ~~~~~~~~~~~~~~~~~~~^^^^^^^^^^^^^
  File "/Users/elgiz/flyexpert/backend/.venv/lib/python3.13/site-packages/django/db/backends/sqlite3/base.py", line 354, in execute
    return super().execute(query, params)
           ~~~~~~~~~~~~~~~^^^^^^^^^^^^^^^
sqlite3.OperationalError: no such table: accounts_userprofile

The above exception was the direct cause of the following exception:

Traceback (most recent call last):
  File "/Users/elgiz/flyexpert/backend/.venv/lib/python3.13/site-packages/django/core/handlers/exception.py", line 55, in inner
    response = get_response(request)
  File "/Users/elgiz/flyexpert/backend/.venv/lib/python3.13/site-packages/django/core/handlers/base.py", line 220, in _get_response
    response = response.render()
  File "/Users/elgiz/flyexpert/backend/.venv/lib/python3.13/site-packages/django/template/response.py", line 114, in render
    self.content = self.rendered_content
                   ^^^^^^^^^^^^^^^^^^^^^
  File "/Users/elgiz/flyexpert/backend/.venv/lib/python3.13/site-packages/django/template/response.py", line 92, in rendered_content
    return template.render(context, self._request)
           ~~~~~~~~~~~~~~~^^^^^^^^^^^^^^^^^^^^^^^^
  File "/Users/elgiz/flyexpert/backend/.venv/lib/python3.13/site-packages/django/template/backends/django.py", line 107, in render
    return self.template.render(context)
           ~~~~~~~~~~~~~~~~~~~~^^^^^^^^^
  File "/Users/elgiz/flyexpert/backend/.venv/lib/python3.13/site-packages/django/template/base.py", line 171, in render
    return self._render(context)
           ~~~~~~~~~~~~^^^^^^^^^
  File "/Users/elgiz/flyexpert/backend/.venv/lib/python3.13/site-packages/django/template/base.py", line 163, in _render
    return self.nodelist.render(context)
           ~~~~~~~~~~~~~~~~~~~~^^^^^^^^^
  File "/Users/elgiz/flyexpert/backend/.venv/lib/python3.13/site-packages/django/template/base.py", line 1008, in render
    return SafeString("".join([node.render_annotated(context) for node in self]))
                               ~~~~~~~~~~~~~~~~~~~~~^^^^^^^^^
  File "/Users/elgiz/flyexpert/backend/.venv/lib/python3.13/site-packages/django/template/base.py", line 969, in render_annotated
    return self.render(context)
           ~~~~~~~~~~~^^^^^^^^^
  File "/Users/elgiz/flyexpert/backend/.venv/lib/python3.13/site-packages/django/template/loader_tags.py", line 159, in render
    return compiled_parent._render(context)
           ~~~~~~~~~~~~~~~~~~~~~~~^^^^^^^^^
  File "/Users/elgiz/flyexpert/backend/.venv/lib/python3.13/site-packages/django/template/base.py", line 163, in _render
    return self.nodelist.render(context)
           ~~~~~~~~~~~~~~~~~~~~^^^^^^^^^
  File "/Users/elgiz/flyexpert/backend/.venv/lib/python3.13/site-packages/django/template/base.py", line 1008, in render
    return SafeString("".join([node.render_annotated(context) for node in self]))
                               ~~~~~~~~~~~~~~~~~~~~~^^^^^^^^^
  File "/Users/elgiz/flyexpert/backend/.venv/lib/python3.13/site-packages/django/template/base.py", line 969, in render_annotated
    return self.render(context)
           ~~~~~~~~~~~^^^^^^^^^
  File "/Users/elgiz/flyexpert/backend/.venv/lib/python3.13/site-packages/django/template/loader_tags.py", line 159, in render
    return compiled_parent._render(context)
           ~~~~~~~~~~~~~~~~~~~~~~~^^^^^^^^^
  File "/Users/elgiz/flyexpert/backend/.venv/lib/python3.13/site-packages/django/template/base.py", line 163, in _render
    return self.nodelist.render(context)
           ~~~~~~~~~~~~~~~~~~~~^^^^^^^^^
  File "/Users/elgiz/flyexpert/backend/.venv/lib/python3.13/site-packages/django/template/base.py", line 1008, in render
    return SafeString("".join([node.render_annotated(context) for node in self]))
                               ~~~~~~~~~~~~~~~~~~~~~^^^^^^^^^
  File "/Users/elgiz/flyexpert/backend/.venv/lib/python3.13/site-packages/django/template/base.py", line 969, in render_annotated
    return self.render(context)
           ~~~~~~~~~~~^^^^^^^^^
  File "/Users/elgiz/flyexpert/backend/.venv/lib/python3.13/site-packages/django/template/loader_tags.py", line 65, in render
    result = block.nodelist.render(context)
  File "/Users/elgiz/flyexpert/backend/.venv/lib/python3.13/site-packages/django/template/base.py", line 1008, in render
    return SafeString("".join([node.render_annotated(context) for node in self]))
                               ~~~~~~~~~~~~~~~~~~~~~^^^^^^^^^
  File "/Users/elgiz/flyexpert/backend/.venv/lib/python3.13/site-packages/django/template/base.py", line 969, in render_annotated
    return self.render(context)
           ~~~~~~~~~~~^^^^^^^^^
  File "/Users/elgiz/flyexpert/backend/.venv/lib/python3.13/site-packages/django/template/loader_tags.py", line 65, in render
    result = block.nodelist.render(context)
  File "/Users/elgiz/flyexpert/backend/.venv/lib/python3.13/site-packages/django/template/base.py", line 1008, in render
    return SafeString("".join([node.render_annotated(context) for node in self]))
                               ~~~~~~~~~~~~~~~~~~~~~^^^^^^^^^
  File "/Users/elgiz/flyexpert/backend/.venv/lib/python3.13/site-packages/django/template/base.py", line 969, in render_annotated
    return self.render(context)
           ~~~~~~~~~~~^^^^^^^^^
  File "/Users/elgiz/flyexpert/backend/.venv/lib/python3.13/site-packages/django/contrib/admin/templatetags/base.py", line 45, in render
    return super().render(context)
           ~~~~~~~~~~~~~~^^^^^^^^^
  File "/Users/elgiz/flyexpert/backend/.venv/lib/python3.13/site-packages/django/template/library.py", line 258, in render
    _dict = self.func(*resolved_args, **resolved_kwargs)
  File "/Users/elgiz/flyexpert/backend/.venv/lib/python3.13/site-packages/django/contrib/admin/templatetags/admin_list.py", line 346, in result_list
    "results": list(results(cl)),
               ~~~~^^^^^^^^^^^^^
  File "/Users/elgiz/flyexpert/backend/.venv/lib/python3.13/site-packages/django/contrib/admin/templatetags/admin_list.py", line 322, in results
    yield ResultList(None, items_for_result(cl, res, None))
          ~~~~~~~~~~^^^^^^^^^^^^^^^^^^^^^^^^^^^^^^^^^^^^^^^
  File "/Users/elgiz/flyexpert/backend/.venv/lib/python3.13/site-packages/django/contrib/admin/templatetags/admin_list.py", line 313, in __init__
    super().__init__(*items)
    ~~~~~~~~~~~~~~~~^^^^^^^^
  File "/Users/elgiz/flyexpert/backend/.venv/lib/python3.13/site-packages/django/contrib/admin/templatetags/admin_list.py", line 218, in items_for_result
    f, attr, value = lookup_field(field_name, result, cl.model_admin)
                     ~~~~~~~~~~~~^^^^^^^^^^^^^^^^^^^^^^^^^^^^^^^^^^^^
  File "/Users/elgiz/flyexpert/backend/.venv/lib/python3.13/site-packages/django/contrib/admin/utils.py", line 299, in lookup_field
    value = attr(obj)
  File "/Users/elgiz/flyexpert/backend/backend/accounts/admin.py", line 19, in bonus
    return obj.userprofile.bonus  # `UserProfile` modelindən bonus məlumatını qaytarır
           ^^^^^^^^^^^^^^^
  File "/Users/elgiz/flyexpert/backend/.venv/lib/python3.13/site-packages/django/db/models/fields/related_descriptors.py", line 520, in __get__
    rel_obj = self.get_queryset(instance=instance).get(**filter_args)
  File "/Users/elgiz/flyexpert/backend/.venv/lib/python3.13/site-packages/django/db/models/query.py", line 645, in get
    num = len(clone)
  File "/Users/elgiz/flyexpert/backend/.venv/lib/python3.13/site-packages/django/db/models/query.py", line 382, in __len__
    self._fetch_all()
    ~~~~~~~~~~~~~~~^^
  File "/Users/elgiz/flyexpert/backend/.venv/lib/python3.13/site-packages/django/db/models/query.py", line 1928, in _fetch_all
    self._result_cache = list(self._iterable_class(self))
                         ~~~~^^^^^^^^^^^^^^^^^^^^^^^^^^^^
  File "/Users/elgiz/flyexpert/backend/.venv/lib/python3.13/site-packages/django/db/models/query.py", line 91, in __iter__
    results = compiler.execute_sql(
        chunked_fetch=self.chunked_fetch, chunk_size=self.chunk_size
    )
  File "/Users/elgiz/flyexpert/backend/.venv/lib/python3.13/site-packages/django/db/models/sql/compiler.py", line 1574, in execute_sql
    cursor.execute(sql, params)
    ~~~~~~~~~~~~~~^^^^^^^^^^^^^
  File "/Users/elgiz/flyexpert/backend/.venv/lib/python3.13/site-packages/django/db/backends/utils.py", line 122, in execute
    return super().execute(sql, params)
           ~~~~~~~~~~~~~~~^^^^^^^^^^^^^
  File "/Users/elgiz/flyexpert/backend/.venv/lib/python3.13/site-packages/django/db/backends/utils.py", line 79, in execute
    return self._execute_with_wrappers(
           ~~~~~~~~~~~~~~~~~~~~~~~~~~~^
        sql, params, many=False, executor=self._execute
        ^^^^^^^^^^^^^^^^^^^^^^^^^^^^^^^^^^^^^^^^^^^^^^^
    )
    ^
  File "/Users/elgiz/flyexpert/backend/.venv/lib/python3.13/site-packages/django/db/backends/utils.py", line 92, in _execute_with_wrappers
    return executor(sql, params, many, context)
  File "/Users/elgiz/flyexpert/backend/.venv/lib/python3.13/site-packages/django/db/backends/utils.py", line 100, in _execute
    with self.db.wrap_database_errors:
         ^^^^^^^^^^^^^^^^^^^^^^^^^^^^
  File "/Users/elgiz/flyexpert/backend/.venv/lib/python3.13/site-packages/django/db/utils.py", line 91, in __exit__
    raise dj_exc_value.with_traceback(traceback) from exc_value
  File "/Users/elgiz/flyexpert/backend/.venv/lib/python3.13/site-packages/django/db/backends/utils.py", line 105, in _execute
    return self.cursor.execute(sql, params)
           ~~~~~~~~~~~~~~~~~~~^^^^^^^^^^^^^
  File "/Users/elgiz/flyexpert/backend/.venv/lib/python3.13/site-packages/django/db/backends/sqlite3/base.py", line 354, in execute
    return super().execute(query, params)
           ~~~~~~~~~~~~~~~^^^^^^^^^^^^^^^
django.db.utils.OperationalError: no such table: accounts_userprofile
ERROR 2025-03-02 03:27:07,428 basehttp "GET /admin/accounts/customuser/ HTTP/1.1" 500 453994
ERROR 2025-03-02 03:27:26,130 log Internal Server Error: /admin/accounts/userprofile/
Traceback (most recent call last):
  File "/Users/elgiz/flyexpert/backend/.venv/lib/python3.13/site-packages/django/db/backends/utils.py", line 105, in _execute
    return self.cursor.execute(sql, params)
           ~~~~~~~~~~~~~~~~~~~^^^^^^^^^^^^^
  File "/Users/elgiz/flyexpert/backend/.venv/lib/python3.13/site-packages/django/db/backends/sqlite3/base.py", line 354, in execute
    return super().execute(query, params)
           ~~~~~~~~~~~~~~~^^^^^^^^^^^^^^^
sqlite3.OperationalError: no such table: accounts_userprofile

The above exception was the direct cause of the following exception:

Traceback (most recent call last):
  File "/Users/elgiz/flyexpert/backend/.venv/lib/python3.13/site-packages/django/core/handlers/exception.py", line 55, in inner
    response = get_response(request)
  File "/Users/elgiz/flyexpert/backend/.venv/lib/python3.13/site-packages/django/core/handlers/base.py", line 197, in _get_response
    response = wrapped_callback(request, *callback_args, **callback_kwargs)
  File "/Users/elgiz/flyexpert/backend/.venv/lib/python3.13/site-packages/django/contrib/admin/options.py", line 718, in wrapper
    return self.admin_site.admin_view(view)(*args, **kwargs)
           ~~~~~~~~~~~~~~~~~~~~~~~~~~~~~~~~^^^^^^^^^^^^^^^^^
  File "/Users/elgiz/flyexpert/backend/.venv/lib/python3.13/site-packages/django/utils/decorators.py", line 188, in _view_wrapper
    result = _process_exception(request, e)
  File "/Users/elgiz/flyexpert/backend/.venv/lib/python3.13/site-packages/django/utils/decorators.py", line 186, in _view_wrapper
    response = view_func(request, *args, **kwargs)
  File "/Users/elgiz/flyexpert/backend/.venv/lib/python3.13/site-packages/django/views/decorators/cache.py", line 80, in _view_wrapper
    response = view_func(request, *args, **kwargs)
  File "/Users/elgiz/flyexpert/backend/.venv/lib/python3.13/site-packages/django/contrib/admin/sites.py", line 241, in inner
    return view(request, *args, **kwargs)
  File "/Users/elgiz/flyexpert/backend/.venv/lib/python3.13/site-packages/django/utils/decorators.py", line 48, in _wrapper
    return bound_method(*args, **kwargs)
  File "/Users/elgiz/flyexpert/backend/.venv/lib/python3.13/site-packages/django/utils/decorators.py", line 188, in _view_wrapper
    result = _process_exception(request, e)
  File "/Users/elgiz/flyexpert/backend/.venv/lib/python3.13/site-packages/django/utils/decorators.py", line 186, in _view_wrapper
    response = view_func(request, *args, **kwargs)
  File "/Users/elgiz/flyexpert/backend/.venv/lib/python3.13/site-packages/django/contrib/admin/options.py", line 2001, in changelist_view
    cl = self.get_changelist_instance(request)
  File "/Users/elgiz/flyexpert/backend/.venv/lib/python3.13/site-packages/django/contrib/admin/options.py", line 866, in get_changelist_instance
    return ChangeList(
        request,
    ...<12 lines>...
        self.search_help_text,
    )
  File "/Users/elgiz/flyexpert/backend/.venv/lib/python3.13/site-packages/django/contrib/admin/views/main.py", line 146, in __init__
    self.get_results(request)
    ~~~~~~~~~~~~~~~~^^^^^^^^^
  File "/Users/elgiz/flyexpert/backend/.venv/lib/python3.13/site-packages/django/contrib/admin/views/main.py", line 313, in get_results
    result_count = paginator.count
                   ^^^^^^^^^^^^^^^
  File "/Users/elgiz/flyexpert/backend/.venv/lib/python3.13/site-packages/django/utils/functional.py", line 47, in __get__
    res = instance.__dict__[self.name] = self.func(instance)
                                         ~~~~~~~~~^^^^^^^^^^
  File "/Users/elgiz/flyexpert/backend/.venv/lib/python3.13/site-packages/django/core/paginator.py", line 110, in count
    return c()
  File "/Users/elgiz/flyexpert/backend/.venv/lib/python3.13/site-packages/django/db/models/query.py", line 620, in count
    return self.query.get_count(using=self.db)
           ~~~~~~~~~~~~~~~~~~~~^^^^^^^^^^^^^^^
  File "/Users/elgiz/flyexpert/backend/.venv/lib/python3.13/site-packages/django/db/models/sql/query.py", line 630, in get_count
    return obj.get_aggregation(using, {"__count": Count("*")})["__count"]
           ~~~~~~~~~~~~~~~~~~~^^^^^^^^^^^^^^^^^^^^^^^^^^^^^^^^
  File "/Users/elgiz/flyexpert/backend/.venv/lib/python3.13/site-packages/django/db/models/sql/query.py", line 616, in get_aggregation
    result = compiler.execute_sql(SINGLE)
  File "/Users/elgiz/flyexpert/backend/.venv/lib/python3.13/site-packages/django/db/models/sql/compiler.py", line 1574, in execute_sql
    cursor.execute(sql, params)
    ~~~~~~~~~~~~~~^^^^^^^^^^^^^
  File "/Users/elgiz/flyexpert/backend/.venv/lib/python3.13/site-packages/django/db/backends/utils.py", line 122, in execute
    return super().execute(sql, params)
           ~~~~~~~~~~~~~~~^^^^^^^^^^^^^
  File "/Users/elgiz/flyexpert/backend/.venv/lib/python3.13/site-packages/django/db/backends/utils.py", line 79, in execute
    return self._execute_with_wrappers(
           ~~~~~~~~~~~~~~~~~~~~~~~~~~~^
        sql, params, many=False, executor=self._execute
        ^^^^^^^^^^^^^^^^^^^^^^^^^^^^^^^^^^^^^^^^^^^^^^^
    )
    ^
  File "/Users/elgiz/flyexpert/backend/.venv/lib/python3.13/site-packages/django/db/backends/utils.py", line 92, in _execute_with_wrappers
    return executor(sql, params, many, context)
  File "/Users/elgiz/flyexpert/backend/.venv/lib/python3.13/site-packages/django/db/backends/utils.py", line 100, in _execute
    with self.db.wrap_database_errors:
         ^^^^^^^^^^^^^^^^^^^^^^^^^^^^
  File "/Users/elgiz/flyexpert/backend/.venv/lib/python3.13/site-packages/django/db/utils.py", line 91, in __exit__
    raise dj_exc_value.with_traceback(traceback) from exc_value
  File "/Users/elgiz/flyexpert/backend/.venv/lib/python3.13/site-packages/django/db/backends/utils.py", line 105, in _execute
    return self.cursor.execute(sql, params)
           ~~~~~~~~~~~~~~~~~~~^^^^^^^^^^^^^
  File "/Users/elgiz/flyexpert/backend/.venv/lib/python3.13/site-packages/django/db/backends/sqlite3/base.py", line 354, in execute
    return super().execute(query, params)
           ~~~~~~~~~~~~~~~^^^^^^^^^^^^^^^
django.db.utils.OperationalError: no such table: accounts_userprofile
ERROR 2025-03-02 03:27:26,138 basehttp "GET /admin/accounts/userprofile/ HTTP/1.1" 500 186460
ERROR 2025-03-02 03:27:46,339 log Internal Server Error: /admin/tours/booking/
Traceback (most recent call last):
  File "/Users/elgiz/flyexpert/backend/.venv/lib/python3.13/site-packages/django/db/backends/utils.py", line 105, in _execute
    return self.cursor.execute(sql, params)
           ~~~~~~~~~~~~~~~~~~~^^^^^^^^^^^^^
  File "/Users/elgiz/flyexpert/backend/.venv/lib/python3.13/site-packages/django/db/backends/sqlite3/base.py", line 354, in execute
    return super().execute(query, params)
           ~~~~~~~~~~~~~~~^^^^^^^^^^^^^^^
sqlite3.OperationalError: no such column: tours_booking.status

The above exception was the direct cause of the following exception:

Traceback (most recent call last):
  File "/Users/elgiz/flyexpert/backend/.venv/lib/python3.13/site-packages/django/core/handlers/exception.py", line 55, in inner
    response = get_response(request)
  File "/Users/elgiz/flyexpert/backend/.venv/lib/python3.13/site-packages/django/core/handlers/base.py", line 197, in _get_response
    response = wrapped_callback(request, *callback_args, **callback_kwargs)
  File "/Users/elgiz/flyexpert/backend/.venv/lib/python3.13/site-packages/django/contrib/admin/options.py", line 718, in wrapper
    return self.admin_site.admin_view(view)(*args, **kwargs)
           ~~~~~~~~~~~~~~~~~~~~~~~~~~~~~~~~^^^^^^^^^^^^^^^^^
  File "/Users/elgiz/flyexpert/backend/.venv/lib/python3.13/site-packages/django/utils/decorators.py", line 188, in _view_wrapper
    result = _process_exception(request, e)
  File "/Users/elgiz/flyexpert/backend/.venv/lib/python3.13/site-packages/django/utils/decorators.py", line 186, in _view_wrapper
    response = view_func(request, *args, **kwargs)
  File "/Users/elgiz/flyexpert/backend/.venv/lib/python3.13/site-packages/django/views/decorators/cache.py", line 80, in _view_wrapper
    response = view_func(request, *args, **kwargs)
  File "/Users/elgiz/flyexpert/backend/.venv/lib/python3.13/site-packages/django/contrib/admin/sites.py", line 241, in inner
    return view(request, *args, **kwargs)
  File "/Users/elgiz/flyexpert/backend/.venv/lib/python3.13/site-packages/django/utils/decorators.py", line 48, in _wrapper
    return bound_method(*args, **kwargs)
  File "/Users/elgiz/flyexpert/backend/.venv/lib/python3.13/site-packages/django/utils/decorators.py", line 188, in _view_wrapper
    result = _process_exception(request, e)
  File "/Users/elgiz/flyexpert/backend/.venv/lib/python3.13/site-packages/django/utils/decorators.py", line 186, in _view_wrapper
    response = view_func(request, *args, **kwargs)
  File "/Users/elgiz/flyexpert/backend/.venv/lib/python3.13/site-packages/django/contrib/admin/options.py", line 2121, in changelist_view
    media = self.media + formset.media
                         ^^^^^^^^^^^^^
  File "/Users/elgiz/flyexpert/backend/.venv/lib/python3.13/site-packages/django/forms/formsets.py", line 521, in media
    if self.forms:
       ^^^^^^^^^^
  File "/Users/elgiz/flyexpert/backend/.venv/lib/python3.13/site-packages/django/utils/functional.py", line 47, in __get__
    res = instance.__dict__[self.name] = self.func(instance)
                                         ~~~~~~~~~^^^^^^^^^^
  File "/Users/elgiz/flyexpert/backend/.venv/lib/python3.13/site-packages/django/forms/formsets.py", line 207, in forms
    for i in range(self.total_form_count())
                   ~~~~~~~~~~~~~~~~~~~~~^^
  File "/Users/elgiz/flyexpert/backend/.venv/lib/python3.13/site-packages/django/forms/formsets.py", line 182, in total_form_count
    initial_forms = self.initial_form_count()
  File "/Users/elgiz/flyexpert/backend/.venv/lib/python3.13/site-packages/django/forms/models.py", line 697, in initial_form_count
    return len(self.get_queryset())
  File "/Users/elgiz/flyexpert/backend/.venv/lib/python3.13/site-packages/django/db/models/query.py", line 382, in __len__
    self._fetch_all()
    ~~~~~~~~~~~~~~~^^
  File "/Users/elgiz/flyexpert/backend/.venv/lib/python3.13/site-packages/django/db/models/query.py", line 1928, in _fetch_all
    self._result_cache = list(self._iterable_class(self))
                         ~~~~^^^^^^^^^^^^^^^^^^^^^^^^^^^^
  File "/Users/elgiz/flyexpert/backend/.venv/lib/python3.13/site-packages/django/db/models/query.py", line 91, in __iter__
    results = compiler.execute_sql(
        chunked_fetch=self.chunked_fetch, chunk_size=self.chunk_size
    )
  File "/Users/elgiz/flyexpert/backend/.venv/lib/python3.13/site-packages/django/db/models/sql/compiler.py", line 1574, in execute_sql
    cursor.execute(sql, params)
    ~~~~~~~~~~~~~~^^^^^^^^^^^^^
  File "/Users/elgiz/flyexpert/backend/.venv/lib/python3.13/site-packages/django/db/backends/utils.py", line 122, in execute
    return super().execute(sql, params)
           ~~~~~~~~~~~~~~~^^^^^^^^^^^^^
  File "/Users/elgiz/flyexpert/backend/.venv/lib/python3.13/site-packages/django/db/backends/utils.py", line 79, in execute
    return self._execute_with_wrappers(
           ~~~~~~~~~~~~~~~~~~~~~~~~~~~^
        sql, params, many=False, executor=self._execute
        ^^^^^^^^^^^^^^^^^^^^^^^^^^^^^^^^^^^^^^^^^^^^^^^
    )
    ^
  File "/Users/elgiz/flyexpert/backend/.venv/lib/python3.13/site-packages/django/db/backends/utils.py", line 92, in _execute_with_wrappers
    return executor(sql, params, many, context)
  File "/Users/elgiz/flyexpert/backend/.venv/lib/python3.13/site-packages/django/db/backends/utils.py", line 100, in _execute
    with self.db.wrap_database_errors:
         ^^^^^^^^^^^^^^^^^^^^^^^^^^^^
  File "/Users/elgiz/flyexpert/backend/.venv/lib/python3.13/site-packages/django/db/utils.py", line 91, in __exit__
    raise dj_exc_value.with_traceback(traceback) from exc_value
  File "/Users/elgiz/flyexpert/backend/.venv/lib/python3.13/site-packages/django/db/backends/utils.py", line 105, in _execute
    return self.cursor.execute(sql, params)
           ~~~~~~~~~~~~~~~~~~~^^^^^^^^^^^^^
  File "/Users/elgiz/flyexpert/backend/.venv/lib/python3.13/site-packages/django/db/backends/sqlite3/base.py", line 354, in execute
    return super().execute(query, params)
           ~~~~~~~~~~~~~~~^^^^^^^^^^^^^^^
django.db.utils.OperationalError: no such column: tours_booking.status
ERROR 2025-03-02 03:27:46,357 basehttp "GET /admin/tours/booking/ HTTP/1.1" 500 197338
